Workbook

Sheet （新）processed_results
A1: 文件名 | B1: 处理时间 | C1: 案例编号 | D1: 案例名称 | E1: 地区 | F1: 学段 | G1: 产业应用现状 | H1: 优势和创新点 | I1: 关键技术路径 | J1: 技术要素 | K1: 工具名称 | L1: 企业名称 | M1: 是否自主研发 | N1: 产品形态 | O1: 产品分类 | P1: 文档内容依据 | Q1: 应用场景（一级） | R1: 应用场景（二级） | S1: 培养方向 | T1: 潜在成效 | U1: 关键技术路径 | V1: 技术要素 | W1: 产业应用现状 | X1: 优势和创新点 | Y1: 学科 | Z1: 工具标准名 | AA1: 公司 | AB1: 省份 | AD1: 产品名（校准） | AE1: 分类标准_产业角度（一级） | AF1: 分类标准_产业角度（二级） | AG1: 分类标准_[教育角度] | AH1: 产品属性 | AI1: 产品名_是否大模型 | AJ1: 省份_更新
A2: 第01号案例_1温州市新田园小学 叶诗婧《数“算”生“动”：AI赋能下运算律教学的新样态》.pdf | B2: 46056.45 | C2: 1 | D2: 数“算”生“动”：AI赋能下运算律教学的新样态 | E2: 温州市 | F2: 小学 | G2: 企业产品以“学习支持工具”为主，学校多通过校本化规则实现教学适配，整体处于规模化应用初期 | H2: 通过动态点子图和AI语音交互，将抽象的运算律转化为可操作的探究过程，实现了概念理解从抽象到直观、思维过程从内隐到外显的突破。 | I2: 学习行为采集 → 学情诊断与画像生成 → 个性化反馈与辅导 → 学习改进 | J2: ["语音识别", "动态可视化", "学习行为分析模型", "教育数据挖掘", "人工智能算法"] | K2: AI学习机 | L2: 易点慧科技有限公司 | M2: TRUE | N2: 硬件 + AI系统 | O2: 平台型综合系统 | P2: 文档中提到“AI学习机作为课堂互动工具，实现个性化教学。” | Q2: 助学 | R2: 智能辅导系统 | S2: 智育 | T2: 学生：深化算理理解、提升表达与推理能力；教师：实现精准诊断与即时干预；学校：形成可复制的“AI+概念教学”范式 | U2: 学习行为采集 → 学情诊断与画像生成 → 个性化反馈与辅导 → 学习改进 | V2: 数据采集层（多模态学习数据采集与融合） 画像诊断层（个性化画像生成、过程性反馈解释） 个性化学习层（即时生成反馈） | W2: 企业产品以“学习支持工具”为主，学校多通过校本化规则实现教学适配，整体处于规模化应用初期 | X2: AI点子图可视化 + AI说理，将抽象运算律转化为可操作模型，实现“理解—表达—诊断”闭环 | Y2: 数学 | Z2: AI学习机 | AA2: 0 | AB2: 浙江省 | AD2: =VLOOKUP($K2,「工具标准名」映射表!$B:$I,3,0) -> AI学习机 | AE2: =VLOOKUP($K2,「工具标准名」映射表!$B:$I,4,0) -> 功能应用层 | AF2: =VLOOKUP($K2,「工具标准名」映射表!$B:$I,5,0) -> 功能应用（教学辅助工具） | AG2: =VLOOKUP($K2,「工具标准名」映射表!$B:$I,6,0) -> 软件工具 | AH2: =VLOOKUP($K2,「工具标准名」映射表!$B:$I,7,0) -> 大语言模型 | AI2: =VLOOKUP($K2,「工具标准名」映射表!$B:$I,8,0) -> 是 | AJ2: 浙江省
A3: 第01号案例_1温州市新田园小学 叶诗婧《数“算”生“动”：AI赋能下运算律教学的新样态》.pdf | B3: 46056.45 | C3: 1 | D3: 数“算”生“动”：AI赋能下运算律教学的新样态 | E3: 温州市 | F3: 小学 | G3: 企业产品以“学习支持工具”为主，学校多通过校本化规则实现教学适配，整体处于规模化应用初期 | H3: 通过动态点子图和AI语音交互，将抽象的运算律转化为可操作的探究过程，实现了概念理解从抽象到直观、思维过程从内隐到外显的突破。 | I3: 学习行为采集 → 学情诊断与画像生成 → 个性化反馈与辅导 → 学习改进 | J3: ["语音识别", "动态可视化", "学习行为分析模型", "教育数据挖掘", "人工智能算法"] | K3: AI语音互动平台 | L3: 易点慧科技有限公司 | M3: TRUE | N3: 软件平台 | O3: Web 教学平台（SaaS） | P3: 文档中描述“集成'易点慧'AI语音互动平台。” | Q3: 助学 | R3: 智能辅导系统 | S3: 智育 | T3: 学生：深化算理理解、提升表达与推理能力；教师：实现精准诊断与即时干预；学校：形成可复制的“AI+概念教学”范式 | U3: 学习行为采集 → 学情诊断与画像生成 → 个性化反馈与辅导 → 学习改进 | V3: 数据采集层（多模态学习数据采集与融合） 画像诊断层（个性化画像生成、过程性反馈解释） 个性化学习层（即时生成反馈） | W3: 企业产品以“学习支持工具”为主，学校多通过校本化规则实现教学适配，整体处于规模化应用初期 | X3: AI点子图可视化 + AI说理，将抽象运算律转化为可操作模型，实现“理解—表达—诊断”闭环 | Y3: 数学 | Z3: AI语音互动平台 | AA3: 0 | AB3: 浙江省 | AD3: =VLOOKUP($K3,「工具标准名」映射表!$B:$I,3,0) -> AI语音互动平台 | AE3: =VLOOKUP($K3,「工具标准名」映射表!$B:$I,4,0) -> 功能应用层 | AF3: =VLOOKUP($K3,「工具标准名」映射表!$B:$I,5,0) -> 功能应用（教学辅助工具） | AG3: =VLOOKUP($K3,「工具标准名」映射表!$B:$I,6,0) -> 软件工具 | AH3: =VLOOKUP($K3,「工具标准名」映射表!$B:$I,7,0) -> 大语言模型 | AI3: =VLOOKUP($K3,「工具标准名」映射表!$B:$I,8,0) -> 是 | AJ3: 浙江省
A4: 第01号案例_1温州市新田园小学 叶诗婧《数“算”生“动”：AI赋能下运算律教学的新样态》.pdf | B4: 46056.45 | C4: 1 | D4: 数“算”生“动”：AI赋能下运算律教学的新样态 | E4: 温州市 | F4: 小学 | G4: 企业产品以“学习支持工具”为主，学校多通过校本化规则实现教学适配，整体处于规模化应用初期 | H4: 通过动态点子图和AI语音交互，将抽象的运算律转化为可操作的探究过程，实现了概念理解从抽象到直观、思维过程从内隐到外显的突破。 | I4: 学习行为采集 → 学情诊断与画像生成 → 个性化反馈与辅导 → 学习改进 | J4: ["语音识别", "动态可视化", "学习行为分析模型", "教育数据挖掘", "人工智能算法"] | K4: 动态点子图生成系统 | L4: 未点名企业 | M4: FALSE | N4: 软件平台 | O4: 平台内嵌功能模块 / 插件 | P4: 文档中提到“利用'豆包'和'DeepSeek'生成动态点子图代码。” | Q4: 助学 | R4: 智能辅导系统 | S4: 智育 | T4: 学生：深化算理理解、提升表达与推理能力；教师：实现精准诊断与即时干预；学校：形成可复制的“AI+概念教学”范式 | U4: 学习行为采集 → 学情诊断与画像生成 → 个性化反馈与辅导 → 学习改进 | V4: 数据采集层（多模态学习数据采集与融合） 画像诊断层（个性化画像生成、过程性反馈解释） 个性化学习层（即时生成反馈） | W4: 企业产品以“学习支持工具”为主，学校多通过校本化规则实现教学适配，整体处于规模化应用初期 | X4: AI点子图可视化 + AI说理，将抽象运算律转化为可操作模型，实现“理解—表达—诊断”闭环 | Y4: 数学 | Z4: 动态点子图生成系统 | AA4: 0 | AB4: 浙江省 | AD4: =VLOOKUP($K4,「工具标准名」映射表!$B:$I,3,0) -> 动态点子图生成系统 | AE4: =VLOOKUP($K4,「工具标准名」映射表!$B:$I,4,0) -> 功能应用层 | AF4: =VLOOKUP($K4,「工具标准名」映射表!$B:$I,5,0) -> 功能应用（平台型综合系统） | AG4: =VLOOKUP($K4,「工具标准名」映射表!$B:$I,6,0) -> 软件工具 | AH4: =VLOOKUP($K4,「工具标准名」映射表!$B:$I,7,0) -> 其他 | AI4: =VLOOKUP($K4,「工具标准名」映射表!$B:$I,8,0) -> 否 | AJ4: 浙江省
A5: 第02号案例_2温州市新田园小学朱朝炜《三维联动：人工智能视域下小学足球运球游戏设计与研究》.pdf | B5: 46056.45 | C5: 2 | D5: 人工智能视域下“三维联动”小学足球运球游戏设计与实践 | E5: 温州市 | F5: 小学 | G5: 已在小学足球运球教学中实践应用，覆盖不同学段学生，适合推广至其他体育项目。 | H5: 通过智慧设备与游戏化教学的结合，提升学生的技术掌握度与体能达标率，解决传统教学中的多项痛点。 | I5: 数据采集 → 动态调整 → 多维反馈 → 技术迁移与应用 | J5: ["数据采集", "动态调整", "多维反馈", "技术迁移", "体能监测"] | K5: AI分析系统 | L5: 未点名企业 | M5: FALSE | N5: 软件平台 | O5: 平台型综合系统 | P5: 文档中提到“AI分析系统与足球运球游戏深度融合，实现技术分解重组、体能精准调控、即时决策干涉。” | Q5: 助学 | R5: 游戏化学习 | S5: 体育 | T5: 学生：提升足球运球技术、体能达标率与课堂参与度；教师：实现精准调控与动态反馈；学校：推动体育教学数字化转型与创新实践。 | U5: 数据采集 → 动态调整 → 多维反馈 | V5: 数据采集层（智慧手环、心率带、AI分析系统）；动态调整层（实时心率监测、体能负荷调控）；反馈层（多源数据融合的精准评价体系） | W5: 企业产品以“智慧体育”与“游戏化教学”为主，整体处于数字化转型的探索阶段，具有较大的推广潜力。 | X5: 构建“技术-体能-应用”三维联动框架，通过游戏化教学实现技术、体能与应用的协同发展，填补传统教学中“数据缺失-调控盲目”的空白。 | Y5: 体育 | Z5: AI分析系统 | AA5: 0 | AB5: 浙江省 | AD5: =VLOOKUP($K5,「工具标准名」映射表!$B:$I,3,0) -> AI分析系统 | AE5: =VLOOKUP($K5,「工具标准名」映射表!$B:$I,4,0) -> 功能应用层 | AF5: =VLOOKUP($K5,「工具标准名」映射表!$B:$I,5,0) -> 功能应用（教学辅助工具） | AG5: =VLOOKUP($K5,「工具标准名」映射表!$B:$I,6,0) -> 硬件设备 | AH5: =VLOOKUP($K5,「工具标准名」映射表!$B:$I,7,0) -> AI智能体 | AI5: =VLOOKUP($K5,「工具标准名」映射表!$B:$I,8,0) -> 否 | AJ5: 浙江省
A7: 第03号案例_3【案例】从赋能到内生：智能评测驱动“教学评一致”的机理与路径探寻.pdf | B7: 46056.45 | C7: 3 | D7: 从赋能到内生：智能评测驱动“教学评一致”的机理与路径探寻 | E7: 温州市 | F7: 小学 | G7: 已在温州市多所小学规模化应用，覆盖44个班级、1980名学生 | H7: 实现了智能技术角色从外部工具赋能到系统内生动力的范式转换，重构了“教学评一致性”的实现机理与路径。 | I7: 数据驱动的教学评一体化模式构建 → 智能语音检测 → 实时语音训练与智能评分 → 个性化学习分析报告生成 | J7: ["语音识别", "数据分析", "智能评测", "个性化学习路径设计", "实时反馈"] | K7: 易点慧语音型学习机 | L7: 易点慧科技有限公司 | M7: FALSE | N7: 硬件 + AI系统 | O7: 平台型综合系统 | P7: 文档中提到“本案例深度融合‘易点慧’听说型学习机，构建了数据驱动的‘教学评’一体化教学模式。” | Q7: 助教 | R7: 智能学情诊断与个性化辅导 | S7: 智育 | T7: 学生：提升语音准确率、增强课堂参与度；教师：实现精准教学与动态调整；学校：形成可复制的教学评一致性模式 | U7: 数据采集 → 学情诊断与分析 → 个性化反馈与辅导 → 教学评一致性实现 | V7: 数据采集层（多模态数据采集与分析） 行为识别层（语音评测与互动分析） 画像诊断层（个性化学情报告生成） 智能策略层（动态教学调整与反馈） | W7: 企业产品以“智能评测与个性化辅导工具”为主，已在多所小学规模化应用，整体处于推广阶段 | X7: 实现了智能评测从外部工具赋能到系统内生动力的转变，构建了“教学评一致性”的动态调整机制，提升了教学效率与学生语言应用能力 | Y7: 英语 | Z7: 易点慧AI | AA7: 浙江易点慧教育科技有限公司 | AB7: 浙江省 | AD7: =VLOOKUP($K7,「工具标准名」映射表!$B:$I,3,0) -> 易点慧AI | AE7: =VLOOKUP($K7,「工具标准名」映射表!$B:$I,4,0) -> 技术层 | AF7: =VLOOKUP($K7,「工具标准名」映射表!$B:$I,5,0) -> 技术层（通用大模型） | AG7: =VLOOKUP($K7,「工具标准名」映射表!$B:$I,6,0) -> 软件工具 | AH7: =VLOOKUP($K7,「工具标准名」映射表!$B:$I,7,0) -> AI智能体 | AI7: =VLOOKUP($K7,「工具标准名」映射表!$B:$I,8,0) -> 否 | AJ7: 浙江省
A8: 第04号案例_AI赋能地理课堂——七大洲轮廓记忆消消乐申报书.docx | B8: 46056.45 | C8: 4 | D8: AI赋能地理课堂--七大洲轮廓记忆消消乐 | E8: 重庆市璧山区 | F8: 初中 | G8: 已在初一地理课堂进行尝试应用，具备规模化推广的潜力 | H8: 通过游戏化学习模式激发学生学习兴趣，实现个性化互动与即时反馈，提升知识点记忆效率。 | I8: AI技术优化教学形式 → 实时交互与自适应挑战 → 动态游戏任务 → 学习主动性提升 | J8: ["AI大模型算法", "Web技术", "即时反馈系统", "用户体验优化"] | K8: 七大洲速记挑战 | L8: 未点名企业 | M8: TRUE | N8: Web应用 | O8: 平台型综合系统 | P8: 文档中提到“开发了一个能够融合‘趣味性、互动性、即时反馈与个性化挑战’于一体的AI网络页面作为教学巩固工具” | Q8: 助学 | R8: 智能辅导系统 | S8: 智育 | T8: 学生：提升知识点记忆效率，增强学习主动性；教师：提供即时反馈与个性化巩固工具；学校：探索AI与基础教育深度融合的实践思路。 | U8: 需求分析 → AI互动速记挑战网页开发 → 界面优化与课堂融合实践 → 持续反馈与迭代优化 | V8: 数据采集层（学生操作数据记录） 行为识别层（学习模式分析） 个性化学习层（即时反馈与挑战） | W8: 企业产品以“轻量化教育应用”为主，能够快速部署，适用于教育资源薄弱地区，整体处于推广阶段。 | X8: 将游戏化学习与地理知识结合，创新性地转变学习模式，提供零门槛的教育应用，促进学生主动学习与课堂互动。 | Y8: 地理 | Z8: 七大洲速记挑战 | AA8: 0 | AB8: 重庆市 | AD8: =VLOOKUP($K8,「工具标准名」映射表!$B:$I,3,0) -> 七大洲速记挑战 | AE8: =VLOOKUP($K8,「工具标准名」映射表!$B:$I,4,0) -> 功能应用层 | AF8: =VLOOKUP($K8,「工具标准名」映射表!$B:$I,5,0) -> 功能应用（Web 教学平台（SaaS）） | AG8: =VLOOKUP($K8,「工具标准名」映射表!$B:$I,6,0) -> 软件工具 | AH8: =VLOOKUP($K8,「工具标准名」映射表!$B:$I,7,0) -> AI智能体 | AI8: =VLOOKUP($K8,「工具标准名」映射表!$B:$I,8,0) -> 否 | AJ8: 重庆市
A9: 第07号案例_案例申报书.docx | B9: 46056.45 | C9: 7 | D9: AI作为“认知协作者”赋能高中数学阅读精品课的跨学科构建与实践 | E9: 重庆市北碚区 | F9: 高中 | G9: 模式具有极强的可复制性，已遴选为重庆市2025年精品课，正处于实践总结阶段 | H9: 通过将AI作为认知协作者，提升备课效率与课程质量，创新性地引入虚拟学生角色解决互动难题。 | I9: 需求分析 → AI赋能的设计流程 → 课程实施 → 评价与反馈 | J9: ["人工智能", "自然语言处理", "知识图谱", "虚拟现实技术", "深度学习"] | K9: DeepSeek | L9: 未点名企业 | M9: FALSE | N9: 软件平台 | O9: Web 教学平台（SaaS） | P9: 文档中提到“通过AI工具，以DeepSeek为例，指令AI，梳理其与文艺复兴绘画、工程制图、CAD、BIM技术的内在逻辑关系。” | Q9: 助教 | R9: 课堂管理 | S9: 智育 | T9: 学生：提升数学抽象能力、空间想象能力及科技伦理观念；教师：提高备课效率与课程质量；学校：推动基础教育资源的优质均衡发展。 | U9: 需求分析 → 课程设计 → AI赋能的设计流程与实践 → 课堂实施 → 课后评价与思辨引导 | V9: 数据采集层（AI工具DeepSeek用于内容整合与框架生成） 行为识别层（AI生成课堂任务与互动设计） 画像诊断层（AI生成思辨性问题） | W9: 该模式具有极强的可复制性，适用于各学科、各学段的精品课、公开课及常规课的教学设计，整体处于推广应用阶段。 | X9: 将AI作为“认知协作者”嵌入课程开发全流程，促进教师角色转变为方案设计者与质量把控者，创新性地引入“数字人”模拟学生进行互动，提升课堂沉浸感与互动性。 | Y9: 数学 | Z9: DeepSeek 大模型 | AA9: 杭州深度求索人工智能基础技术研究有限公司 | AB9: 重庆市 | AD9: =VLOOKUP($K9,「工具标准名」映射表!$B:$I,3,0) -> DeepSeek 大模型 | AE9: =VLOOKUP($K9,「工具标准名」映射表!$B:$I,4,0) -> 功能应用层 | AF9: =VLOOKUP($K9,「工具标准名」映射表!$B:$I,5,0) -> 功能应用（教学辅助工具） | AG9: =VLOOKUP($K9,「工具标准名」映射表!$B:$I,6,0) -> 软件工具 | AH9: =VLOOKUP($K9,「工具标准名」映射表!$B:$I,7,0) -> AI智能体 | AI9: =VLOOKUP($K9,「工具标准名」映射表!$B:$I,8,0) -> 否 | AJ9: 重庆市
A10: 第07号案例_案例申报书.docx | B10: 46056.45 | C10: 7 | D10: AI作为“认知协作者”赋能高中数学阅读精品课的跨学科构建与实践 | E10: 重庆市北碚区 | F10: 高中 | G10: 模式具有极强的可复制性，已遴选为重庆市2025年精品课，正处于实践总结阶段 | H10: 通过将AI作为认知协作者，提升备课效率与课程质量，创新性地引入虚拟学生角色解决互动难题。 | I10: 需求分析 → AI赋能的设计流程 → 课程实施 → 评价与反馈 | J10: ["人工智能", "自然语言处理", "知识图谱", "虚拟现实技术", "深度学习"] | K10: 可灵AI | L10: 未点名企业 | M10: FALSE | N10: 软件平台 | O10: Web 教学平台（SaaS） | P10: 文档中描述“利用‘可灵AI’生成数字人，数字人模拟学生分享。” | Q10: 助教 | R10: 课堂管理 | S10: 智育 | T10: 学生：提升数学抽象能力、空间想象能力及科技伦理观念；教师：提高备课效率与课程质量；学校：推动基础教育资源的优质均衡发展。 | U10: 需求分析 → 课程设计 → AI赋能的设计流程与实践 → 课堂实施 → 课后评价与思辨引导 | V10: 数据采集层（AI工具DeepSeek用于内容整合与框架生成） 行为识别层（AI生成课堂任务与互动设计） 画像诊断层（AI生成思辨性问题） | W10: 该模式具有极强的可复制性，适用于各学科、各学段的精品课、公开课及常规课的教学设计，整体处于推广应用阶段。 | X10: 将AI作为“认知协作者”嵌入课程开发全流程，促进教师角色转变为方案设计者与质量把控者，创新性地引入“数字人”模拟学生进行互动，提升课堂沉浸感与互动性。 | Y10: 数学 | Z10: 可灵AI | AA10: 北京快手科技有限公司 | AB10: 重庆市 | AD10: =VLOOKUP($K10,「工具标准名」映射表!$B:$I,3,0) -> 可灵AI | AE10: =VLOOKUP($K10,「工具标准名」映射表!$B:$I,4,0) -> 功能应用层 | AF10: =VLOOKUP($K10,「工具标准名」映射表!$B:$I,5,0) -> 功能应用层（AI智能体） | AG10: =VLOOKUP($K10,「工具标准名」映射表!$B:$I,6,0) -> 软件工具 | AH10: =VLOOKUP($K10,「工具标准名」映射表!$B:$I,7,0) -> AI智能体 | AI10: =VLOOKUP($K10,「工具标准名」映射表!$B:$I,8,0) -> 是 | AJ10: 重庆市
A11: 第07号案例_案例申报书.docx | B11: 46056.45 | C11: 7 | D11: AI作为“认知协作者”赋能高中数学阅读精品课的跨学科构建与实践 | E11: 重庆市北碚区 | F11: 高中 | G11: 模式具有极强的可复制性，已遴选为重庆市2025年精品课，正处于实践总结阶段 | H11: 通过将AI作为认知协作者，提升备课效率与课程质量，创新性地引入虚拟学生角色解决互动难题。 | I11: 需求分析 → AI赋能的设计流程 → 课程实施 → 评价与反馈 | J11: ["人工智能", "自然语言处理", "知识图谱", "虚拟现实技术", "深度学习"] | K11: 豆包 | L11: 未点名企业 | M11: FALSE | N11: 软件平台 | O11: Web 教学平台（SaaS） | P11: 文档中提到“借助‘豆包’图生图技术生成鸟巢高清图片。” | Q11: 助教 | R11: 课堂管理 | S11: 智育 | T11: 学生：提升数学抽象能力、空间想象能力及科技伦理观念；教师：提高备课效率与课程质量；学校：推动基础教育资源的优质均衡发展。 | U11: 需求分析 → 课程设计 → AI赋能的设计流程与实践 → 课堂实施 → 课后评价与思辨引导 | V11: 数据采集层（AI工具DeepSeek用于内容整合与框架生成） 行为识别层（AI生成课堂任务与互动设计） 画像诊断层（AI生成思辨性问题） | W11: 该模式具有极强的可复制性，适用于各学科、各学段的精品课、公开课及常规课的教学设计，整体处于推广应用阶段。 | X11: 将AI作为“认知协作者”嵌入课程开发全流程，促进教师角色转变为方案设计者与质量把控者，创新性地引入“数字人”模拟学生进行互动，提升课堂沉浸感与互动性。 | Y11: 数学 | Z11: 豆包 | AA11: 北京春田知韵科技有限公司 | AB11: 重庆市 | AD11: =VLOOKUP($K11,「工具标准名」映射表!$B:$I,3,0) -> 豆包 | AE11: =VLOOKUP($K11,「工具标准名」映射表!$B:$I,4,0) -> 功能应用层 | AF11: =VLOOKUP($K11,「工具标准名」映射表!$B:$I,5,0) -> 功能应用（教学辅助工具） | AG11: =VLOOKUP($K11,「工具标准名」映射表!$B:$I,6,0) -> 软件工具 | AH11: =VLOOKUP($K11,「工具标准名」映射表!$B:$I,7,0) -> 其他 | AI11: =VLOOKUP($K11,「工具标准名」映射表!$B:$I,8,0) -> 否 | AJ11: 重庆市
A12: 第08号案例_8川外科中-《AI智教分析：教学相长的协同创新》案例.docx | B12: 46056.45 | C12: 8 | D12: AI智教分析：教学相长的协同创新 | E12: 重庆高新区 | F12: 初中 | G12: 项目处于实施阶段，正在构建智能化教学体系，推进教育数字化转型。 | H12: 通过构建学生和教师的数字画像，实现个性化教育和精准教学评估，推动教育决策的科学化。 | I12: 数据采集与汇聚 → 学生与教师数字画像构建 → 个性化教学与精准评估 → 教学决策优化 | J12: ["数据挖掘", "机器学习", "自然语言处理", "图像识别", "时间序列分析"] | K12: 未来教室 | L12: 未点名企业 | M12: FALSE | N12: 硬件 + AI系统 | O12: 平台型综合系统 | P12: 文档中提到“未来教室将全方位、全过程记录的学生课堂行为数据” | Q12: 助学 | R12: 智能辅导系统 | S12: 智育 | T12: 学生：实现个性化学习与成长；教师：提升教学质量与策略调整能力；学校：推动教育资源的合理配置与管理决策的科学化。 | U12: 数据采集与汇聚 → 学生与教师数字画像构建 → 个性化教学与精准评估 → 教学决策优化 | V12: 数据采集层（多源数据采集与融合） 画像诊断层（学生与教师数字画像生成、学习行为分析） 智能策略层（个性化学习路径推荐、教学策略调整） | W12: 企业产品以'学习支持工具'为主，学校通过智能化教学体系实现个性化教育，整体处于探索与应用阶段。 | X12: 构建数据驱动的智能教育生态，形成学生与教师之间的动态反馈闭环，实现个性化教学与精准评估的有效结合。 | Y12: 未提及 | Z12: 未来教室 | AA12: 0 | AB12: 重庆市 | AD12: =VLOOKUP($K12,「工具标准名」映射表!$B:$I,3,0) -> 未来教室 | AE12: =VLOOKUP($K12,「工具标准名」映射表!$B:$I,4,0) -> 功能应用层 | AF12: =VLOOKUP($K12,「工具标准名」映射表!$B:$I,5,0) -> 功能应用（平台型综合系统） | AG12: =VLOOKUP($K12,「工具标准名」映射表!$B:$I,6,0) -> 虚拟教室 | AH12: =VLOOKUP($K12,「工具标准名」映射表!$B:$I,7,0) -> AI智能体 | AI12: =VLOOKUP($K12,「工具标准名」映射表!$B:$I,8,0) -> 否 | AJ12: 重庆市
A13: 第08号案例_8川外科中-《AI智教分析：教学相长的协同创新》案例.docx | B13: 46056.45 | C13: 8 | D13: AI智教分析：教学相长的协同创新 | E13: 重庆高新区 | F13: 初中 | G13: 项目处于实施阶段，正在构建智能化教学体系，推进教育数字化转型。 | H13: 通过构建学生和教师的数字画像，实现个性化教育和精准教学评估，推动教育决策的科学化。 | I13: 数据采集与汇聚 → 学生与教师数字画像构建 → 个性化教学与精准评估 → 教学决策优化 | J13: ["数据挖掘", "机器学习", "自然语言处理", "图像识别", "时间序列分析"] | K13: 壹教云系统 | L13: 未点名企业 | M13: FALSE | N13: 软件平台 | O13: Web 教学平台（SaaS） | P13: 文档中提到“通过壹教云线上作业提交平台，广泛收集学生作业数据” | Q13: 助学 | R13: 智能辅导系统 | S13: 智育 | T13: 学生：实现个性化学习与成长；教师：提升教学质量与策略调整能力；学校：推动教育资源的合理配置与管理决策的科学化。 | U13: 数据采集与汇聚 → 学生与教师数字画像构建 → 个性化教学与精准评估 → 教学决策优化 | V13: 数据采集层（多源数据采集与融合） 画像诊断层（学生与教师数字画像生成、学习行为分析） 智能策略层（个性化学习路径推荐、教学策略调整） | W13: 企业产品以'学习支持工具'为主，学校通过智能化教学体系实现个性化教育，整体处于探索与应用阶段。 | X13: 构建数据驱动的智能教育生态，形成学生与教师之间的动态反馈闭环，实现个性化教学与精准评估的有效结合。 | Y13: 未提及 | Z13: 壹教云系统 | AA13: 0 | AB13: 重庆市 | AD13: =VLOOKUP($K13,「工具标准名」映射表!$B:$I,3,0) -> 壹教云系统 | AE13: =VLOOKUP($K13,「工具标准名」映射表!$B:$I,4,0) -> 功能应用层 | AF13: =VLOOKUP($K13,「工具标准名」映射表!$B:$I,5,0) -> 功能应用（Web 教学平台（SaaS）） | AG13: =VLOOKUP($K13,「工具标准名」映射表!$B:$I,6,0) -> 软件工具 | AH13: =VLOOKUP($K13,「工具标准名」映射表!$B:$I,7,0) -> AI智能体 | AI13: =VLOOKUP($K13,「工具标准名」映射表!$B:$I,8,0) -> 否 | AJ13: 重庆市
A14: 第09号案例_贾晓莹“人工智能 基础教育”典型应用场景案例(2).docx | B14: 46056.45 | C14: 9 | D14: 盛情邀约——海河中学130周年校庆邀请函设计 | E14: 天津市 | F14: 初中 | G14: 该案例在美术课堂中应用，正在探索美育与技术的深度融合，处于推广阶段。 | H14: 通过AI技术与美术教学的结合，提升学生对校史的情感认同，创新了美术与德育的融合教学模式。 | I14: 需求分析 → 技术研发与个性化定制 → 应用优化 → 案例推广 | J14: ["AI数字人", "视频生成技术", "设计辅助工具", "互动问答模式", "动态资源推送"] | K14: 梦AI软件 | L14: 未点名企业 | M14: FALSE | N14: 软件平台 | O14: 平台型综合系统 | P14: 文档中提到“通过轻量级AI工具（即梦AI软件）完成定制” | Q14: 助学 | R14: 情境式学习 | S14: 美育 | T14: 学生：掌握折叠式立体请柬的设计与制作技能，理解校史内涵，建立对母校的情感认同；教师：探索融合教学模式；学校：通过学生创作的邀请函传递校庆温度，增强师生、家校的凝聚力。 | U14: 需求分析 → 技术研发与个性化定制 → 应用优化 → 案例创新突破 | V14: 数据采集层（师生访谈、家校问卷） 行为识别层（教师与学生的互动分析） 智能策略层（个性化教学策略生成） 个性化学习层（动态推送适配资源） | W14: 企业产品以“学习支持工具”为主，学校多通过校本化规则实现教学适配，整体处于规模化应用初期。 | X14: 突破传统单向灌输，构建双师协同与项目式学习，利用AI技术提升课堂参与度，增强学生对校史文化的理解与情感共鸣。 | Y14: 美术 | Z14: 梦AI软件 | AA14: 0 | AB14: 天津市 | AD14: =VLOOKUP($K14,「工具标准名」映射表!$B:$I,3,0) -> #N/A | AE14: =VLOOKUP($K14,「工具标准名」映射表!$B:$I,4,0) -> #N/A | AF14: =VLOOKUP($K14,「工具标准名」映射表!$B:$I,5,0) -> #N/A | AG14: =VLOOKUP($K14,「工具标准名」映射表!$B:$I,6,0) -> #N/A | AH14: =VLOOKUP($K14,「工具标准名」映射表!$B:$I,7,0) -> #N/A | AI14: =VLOOKUP($K14,「工具标准名」映射表!$B:$I,8,0) -> #N/A | AJ14: 天津市
A15: 第09号案例_贾晓莹“人工智能 基础教育”典型应用场景案例(2).docx | B15: 46056.45 | C15: 9 | D15: 盛情邀约——海河中学130周年校庆邀请函设计 | E15: 天津市 | F15: 初中 | G15: 该案例在美术课堂中应用，正在探索美育与技术的深度融合，处于推广阶段。 | H15: 通过AI技术与美术教学的结合，提升学生对校史的情感认同，创新了美术与德育的融合教学模式。 | I15: 需求分析 → 技术研发与个性化定制 → 应用优化 → 案例推广 | J15: ["AI数字人", "视频生成技术", "设计辅助工具", "互动问答模式", "动态资源推送"] | K15: 剪映AI扩图 | L15: 未点名企业 | M15: FALSE | N15: 软件平台 | O15: 平台型综合系统 | P15: 文档中提到“利用AI视频工具（如剪映AI扩图）” | Q15: 助学 | R15: 情境式学习 | S15: 美育 | T15: 学生：掌握折叠式立体请柬的设计与制作技能，理解校史内涵，建立对母校的情感认同；教师：探索融合教学模式；学校：通过学生创作的邀请函传递校庆温度，增强师生、家校的凝聚力。 | U15: 需求分析 → 技术研发与个性化定制 → 应用优化 → 案例创新突破 | V15: 数据采集层（师生访谈、家校问卷） 行为识别层（教师与学生的互动分析） 智能策略层（个性化教学策略生成） 个性化学习层（动态推送适配资源） | W15: 企业产品以“学习支持工具”为主，学校多通过校本化规则实现教学适配，整体处于规模化应用初期。 | X15: 突破传统单向灌输，构建双师协同与项目式学习，利用AI技术提升课堂参与度，增强学生对校史文化的理解与情感共鸣。 | Y15: 美术 | Z15: 剪映AI | AA15: 深圳市脸萌科技有限公司 | AB15: 天津市 | AD15: =VLOOKUP($K15,「工具标准名」映射表!$B:$I,3,0) -> 剪映AI | AE15: =VLOOKUP($K15,「工具标准名」映射表!$B:$I,4,0) -> 功能应用层 | AF15: =VLOOKUP($K15,「工具标准名」映射表!$B:$I,5,0) -> 功能应用层（AI智能体） | AG15: =VLOOKUP($K15,「工具标准名」映射表!$B:$I,6,0) -> 软件工具 | AH15: =VLOOKUP($K15,「工具标准名」映射表!$B:$I,7,0) -> AI智能体 | AI15: =VLOOKUP($K15,「工具标准名」映射表!$B:$I,8,0) -> 是 | AJ15: 天津市
A16: 第09号案例_贾晓莹“人工智能 基础教育”典型应用场景案例(2).docx | B16: 46056.45 | C16: 9 | D16: 盛情邀约——海河中学130周年校庆邀请函设计 | E16: 天津市 | F16: 初中 | G16: 该案例在美术课堂中应用，正在探索美育与技术的深度融合，处于推广阶段。 | H16: 通过AI技术与美术教学的结合，提升学生对校史的情感认同，创新了美术与德育的融合教学模式。 | I16: 需求分析 → 技术研发与个性化定制 → 应用优化 → 案例推广 | J16: ["AI数字人", "视频生成技术", "设计辅助工具", "互动问答模式", "动态资源推送"] | K16: 豆包软件 | L16: 未点名企业 | M16: FALSE | N16: 软件平台 | O16: 教学辅助工具（工具型） | P16: 文档中提到“利用豆包软件定制极简版设计辅助包” | Q16: 助学 | R16: 情境式学习 | S16: 美育 | T16: 学生：掌握折叠式立体请柬的设计与制作技能，理解校史内涵，建立对母校的情感认同；教师：探索融合教学模式；学校：通过学生创作的邀请函传递校庆温度，增强师生、家校的凝聚力。 | U16: 需求分析 → 技术研发与个性化定制 → 应用优化 → 案例创新突破 | V16: 数据采集层（师生访谈、家校问卷） 行为识别层（教师与学生的互动分析） 智能策略层（个性化教学策略生成） 个性化学习层（动态推送适配资源） | W16: 企业产品以“学习支持工具”为主，学校多通过校本化规则实现教学适配，整体处于规模化应用初期。 | X16: 突破传统单向灌输，构建双师协同与项目式学习，利用AI技术提升课堂参与度，增强学生对校史文化的理解与情感共鸣。 | Y16: 美术 | Z16: 豆包 | AA16: 北京春田知韵科技有限公司 | AB16: 天津市 | AD16: =VLOOKUP($K16,「工具标准名」映射表!$B:$I,3,0) -> 豆包 | AE16: =VLOOKUP($K16,「工具标准名」映射表!$B:$I,4,0) -> 功能应用层 | AF16: =VLOOKUP($K16,「工具标准名」映射表!$B:$I,5,0) -> 功能应用（平台型综合系统） | AG16: =VLOOKUP($K16,「工具标准名」映射表!$B:$I,6,0) -> 软件工具 | AH16: =VLOOKUP($K16,「工具标准名」映射表!$B:$I,7,0) -> 其他 | AI16: =VLOOKUP($K16,「工具标准名」映射表!$B:$I,8,0) -> 否 | AJ16: 天津市
A17: 第10号案例_10人工智能赋能初中英语互动教学：破解课程参与难度，提升教学效能.docx | B17: 46056.452 | C17: 10 | D17: 人工智能赋能初中英语互动教学：破解课程参与难度，提升教学效能 | E17: 重庆市璧山区 | F17: 初中 | G17: 当前该模式在本校初中英语教学全面应用，具备规模化推广条件 | H17: 重构低压力-高互动教学模式，提升学生开口率与参与度，实时反馈与个性化推送有效满足学生差异化需求。 | I17: 需求分析 → 技术适配 → 应用优化 → 教学反馈与个性化指导 | J17: ["AI语音评测", "实时数据分析", "个性化学习推送", "自动批改系统", "教育数据安全"] | K17: AI语音互动平台 | L17: 科大讯飞 | M17: FALSE | N17: 软件平台 | O17: Web 教学平台（SaaS） | P17: 文档中提到“选用符合教育数据安全标准的第三方智能平台（如科大讯飞智慧课堂）” | Q17: 助学 | R17: 智能辅导系统 | S17: 智育 | T17: 学生：提升课堂参与度与英语能力；教师：实现实时反馈与精准教学；学校：形成可复制的AI教学模式 | U17: 需求分析 → 技术适配 → 应用优化 → 教学反馈 | V17: 数据采集层（实时语音评测、班级学情报告） 行为识别层（学生参与率与正确率统计） 个性化学习层（智能分层推送、个性化巩固练习） | W17: 企业产品以"学习支持工具"为主，学校多通过校本化规则实现教学适配，整体处于规模化应用初期 | X17: 重构低压力高互动教学模式，提升学生开口率与参与度，确保个性化教学落地，适合薄弱学校推广 | Y17: 英语 | Z17: AI语音互动平台 | AA17: 0 | AB17: 重庆市 | AD17: =VLOOKUP($K17,「工具标准名」映射表!$B:$I,3,0) -> AI语音互动平台 | AE17: =VLOOKUP($K17,「工具标准名」映射表!$B:$I,4,0) -> 功能应用层 | AF17: =VLOOKUP($K17,「工具标准名」映射表!$B:$I,5,0) -> 功能应用（教学辅助工具） | AG17: =VLOOKUP($K17,「工具标准名」映射表!$B:$I,6,0) -> 软件工具 | AH17: =VLOOKUP($K17,「工具标准名」映射表!$B:$I,7,0) -> 大语言模型 | AI17: =VLOOKUP($K17,「工具标准名」映射表!$B:$I,8,0) -> 是 | AJ17: 重庆市
A18: 第11号案例_申报书 隆昌市向阳路小学 黎恩旭 《用彩墨画鱼》.docx | B18: 46056.453 | C18: 11 | D18: AI赋能跨学科融合：小学美术《用彩墨画鱼》全流程智能教学实践 | E18: 隆昌市 | F18: 小学 | G18: 该案例已在本校四年级美术课堂落地，具备大规模推广的成熟条件与广阔前景 | H18: 首创‘AI+IP主题+跨学科三维融合’教学范式，实现抽象知识可视化、互动化、跨学科融合，提升学生核心素养。 | I18: 需求分析 → 技术适配与定制 → 全流程应用实践与优化 → 应用迭代优化 | J18: ["动画建模", "动态转化", "语音合成", "互动答题系统", "3D虚拟展馆"] | K18: 即梦AI | L18: 未点名企业 | M18: FALSE | N18: 软件平台 | O18: Web 教学平台（SaaS） | P18: 文档中提到‘选用即梦AI作为核心技术支撑，定制开发三大功能模块’ | Q18: 助学 | R18: 智能辅导系统 | S18: 美育 | T18: 学生：提升审美感知、艺术表现与文化理解能力；教师：实现跨学科教学的有效融合；学校：形成可复制的‘AI+学科’教学模式，推动基础教育智能化转型。 | U18: 需求分析 → 技术适配与定制 → 全流程应用实践与优化 → 应用迭代优化 | V18: 数据采集层（动态赋能模块、语音合成模块） 行为识别层（互动答题系统、知识认知场景化） 画像诊断层（虚拟展馆展示学生作品） | W18: 该案例已在本校四年级美术课堂落地，具备大规模推广的成熟条件与广阔前景，推动基础教育数字化转型。 | X18: 首创‘AI+IP主题+跨学科三维融合’教学范式，通过动态演示与虚拟展馆展示，打破学科壁垒，实现知识的可视化与互动化，提升学生的参与感与创作成就感。 | Y18: 美术 | Z18: 即梦AI | AA18: 深圳市脸萌科技有限公司 | AB18: 四川省 | AD18: =VLOOKUP($K18,「工具标准名」映射表!$B:$I,3,0) -> 即梦AI | AE18: =VLOOKUP($K18,「工具标准名」映射表!$B:$I,4,0) -> 功能应用层 | AF18: =VLOOKUP($K18,「工具标准名」映射表!$B:$I,5,0) -> 功能应用（生成式AI应用-图像类） | AG18: =VLOOKUP($K18,「工具标准名」映射表!$B:$I,6,0) -> 软件工具 | AH18: =VLOOKUP($K18,「工具标准名」映射表!$B:$I,7,0) -> AI智能体 | AI18: =VLOOKUP($K18,「工具标准名」映射表!$B:$I,8,0) -> 是 | AJ18: 四川省
A19: 第11号案例_申报书 隆昌市向阳路小学 黎恩旭 《用彩墨画鱼》.docx | B19: 46056.453 | C19: 11 | D19: AI赋能跨学科融合：小学美术《用彩墨画鱼》全流程智能教学实践 | E19: 隆昌市 | F19: 小学 | G19: 该案例已在本校四年级美术课堂落地，具备大规模推广的成熟条件与广阔前景 | H19: 首创‘AI+IP主题+跨学科三维融合’教学范式，实现抽象知识可视化、互动化、跨学科融合，提升学生核心素养。 | I19: 需求分析 → 技术适配与定制 → 全流程应用实践与优化 → 应用迭代优化 | J19: ["动画建模", "动态转化", "语音合成", "互动答题系统", "3D虚拟展馆"] | K19: 希沃白板 | L19: 未点名企业 | M19: FALSE | N19: 硬件 + 软件系统 | O19: 教学辅助工具（工具型） | P19: 文档中提到‘联动希沃白板搭建互动答题系统’ | Q19: 助学 | R19: 智能辅导系统 | S19: 美育 | T19: 学生：提升审美感知、艺术表现与文化理解能力；教师：实现跨学科教学的有效融合；学校：形成可复制的‘AI+学科’教学模式，推动基础教育智能化转型。 | U19: 需求分析 → 技术适配与定制 → 全流程应用实践与优化 → 应用迭代优化 | V19: 数据采集层（动态赋能模块、语音合成模块） 行为识别层（互动答题系统、知识认知场景化） 画像诊断层（虚拟展馆展示学生作品） | W19: 该案例已在本校四年级美术课堂落地，具备大规模推广的成熟条件与广阔前景，推动基础教育数字化转型。 | X19: 首创‘AI+IP主题+跨学科三维融合’教学范式，通过动态演示与虚拟展馆展示，打破学科壁垒，实现知识的可视化与互动化，提升学生的参与感与创作成就感。 | Y19: 美术 | Z19: 希沃白板 | AA19: 广州视源电子科技股份有限公司 | AB19: 四川省 | AD19: =VLOOKUP($K19,「工具标准名」映射表!$B:$I,3,0) -> 希沃白板 | AE19: =VLOOKUP($K19,「工具标准名」映射表!$B:$I,4,0) -> 功能应用层 | AF19: =VLOOKUP($K19,「工具标准名」映射表!$B:$I,5,0) -> 功能应用（教学辅助工具） | AG19: =VLOOKUP($K19,「工具标准名」映射表!$B:$I,6,0) -> 软件工具 | AH19: =VLOOKUP($K19,「工具标准名」映射表!$B:$I,7,0) -> AI智能体 | AI19: =VLOOKUP($K19,「工具标准名」映射表!$B:$I,8,0) -> 否 | AJ19: 四川省
A20: 第11号案例_申报书 隆昌市向阳路小学 黎恩旭 《用彩墨画鱼》.docx | B20: 46056.453 | C20: 11 | D20: AI赋能跨学科融合：小学美术《用彩墨画鱼》全流程智能教学实践 | E20: 隆昌市 | F20: 小学 | G20: 该案例已在本校四年级美术课堂落地，具备大规模推广的成熟条件与广阔前景 | H20: 首创‘AI+IP主题+跨学科三维融合’教学范式，实现抽象知识可视化、互动化、跨学科融合，提升学生核心素养。 | I20: 需求分析 → 技术适配与定制 → 全流程应用实践与优化 → 应用迭代优化 | J20: ["动画建模", "动态转化", "语音合成", "互动答题系统", "3D虚拟展馆"] | K20: 微信“元美”小程序 | L20: 未点名企业 | M20: FALSE | N20: 软件平台 | O20: Web 教学平台（SaaS） | P20: 文档中提到‘对接微信“元美”小程序，开发3D虚拟展馆定制模板’ | Q20: 助学 | R20: 智能辅导系统 | S20: 美育 | T20: 学生：提升审美感知、艺术表现与文化理解能力；教师：实现跨学科教学的有效融合；学校：形成可复制的‘AI+学科’教学模式，推动基础教育智能化转型。 | U20: 需求分析 → 技术适配与定制 → 全流程应用实践与优化 → 应用迭代优化 | V20: 数据采集层（动态赋能模块、语音合成模块） 行为识别层（互动答题系统、知识认知场景化） 画像诊断层（虚拟展馆展示学生作品） | W20: 该案例已在本校四年级美术课堂落地，具备大规模推广的成熟条件与广阔前景，推动基础教育数字化转型。 | X20: 首创‘AI+IP主题+跨学科三维融合’教学范式，通过动态演示与虚拟展馆展示，打破学科壁垒，实现知识的可视化与互动化，提升学生的参与感与创作成就感。 | Y20: 美术 | Z20: 微信“元美”小程序 | AA20: 0 | AB20: 四川省 | AD20: =VLOOKUP($K20,「工具标准名」映射表!$B:$I,3,0) -> 微信“元美”小程序 | AE20: =VLOOKUP($K20,「工具标准名」映射表!$B:$I,4,0) -> 功能应用层 | AF20: =VLOOKUP($K20,「工具标准名」映射表!$B:$I,5,0) -> 功能应用层（移动端 App） | AG20: =VLOOKUP($K20,「工具标准名」映射表!$B:$I,6,0) -> 软件工具 | AH20: =VLOOKUP($K20,「工具标准名」映射表!$B:$I,7,0) -> AI智能体 | AI20: =VLOOKUP($K20,「工具标准名」映射表!$B:$I,8,0) -> 否 | AJ20: 四川省
A21: 第11号案例_申报书 隆昌市向阳路小学 黎恩旭 《用彩墨画鱼》.docx | B21: 46056.453 | C21: 11 | D21: AI赋能跨学科融合：小学美术《用彩墨画鱼》全流程智能教学实践 | E21: 隆昌市 | F21: 小学 | G21: 该案例已在本校四年级美术课堂落地，具备大规模推广的成熟条件与广阔前景 | H21: 首创‘AI+IP主题+跨学科三维融合’教学范式，实现抽象知识可视化、互动化、跨学科融合，提升学生核心素养。 | I21: 需求分析 → 技术适配与定制 → 全流程应用实践与优化 → 应用迭代优化 | J21: ["动画建模", "动态转化", "语音合成", "互动答题系统", "3D虚拟展馆"] | K21: Photoshop | L21: 未点名企业 | M21: FALSE | N21: 软件平台 | O21: 教学辅助工具（工具型） | P21: 文档中提到‘融合Photoshop、剪映等工具，完成“丹尼”动画的修图与配音’ | Q21: 助学 | R21: 智能辅导系统 | S21: 美育 | T21: 学生：提升审美感知、艺术表现与文化理解能力；教师：实现跨学科教学的有效融合；学校：形成可复制的‘AI+学科’教学模式，推动基础教育智能化转型。 | U21: 需求分析 → 技术适配与定制 → 全流程应用实践与优化 → 应用迭代优化 | V21: 数据采集层（动态赋能模块、语音合成模块） 行为识别层（互动答题系统、知识认知场景化） 画像诊断层（虚拟展馆展示学生作品） | W21: 该案例已在本校四年级美术课堂落地，具备大规模推广的成熟条件与广阔前景，推动基础教育数字化转型。 | X21: 首创‘AI+IP主题+跨学科三维融合’教学范式，通过动态演示与虚拟展馆展示，打破学科壁垒，实现知识的可视化与互动化，提升学生的参与感与创作成就感。 | Y21: 美术 | Z21: Photoshop | AA21: 0 | AB21: 四川省 | AD21: =VLOOKUP($K21,「工具标准名」映射表!$B:$I,3,0) -> Photoshop | AE21: =VLOOKUP($K21,「工具标准名」映射表!$B:$I,4,0) -> 功能应用层 | AF21: =VLOOKUP($K21,「工具标准名」映射表!$B:$I,5,0) -> 功能应用（Web 教学平台（SaaS）） | AG21: =VLOOKUP($K21,「工具标准名」映射表!$B:$I,6,0) -> 硬件设备 | AH21: =VLOOKUP($K21,「工具标准名」映射表!$B:$I,7,0) -> 其他 | AI21: =VLOOKUP($K21,「工具标准名」映射表!$B:$I,8,0) -> 否 | AJ21: 四川省
A22: 第11号案例_申报书 隆昌市向阳路小学 黎恩旭 《用彩墨画鱼》.docx | B22: 46056.453 | C22: 11 | D22: AI赋能跨学科融合：小学美术《用彩墨画鱼》全流程智能教学实践 | E22: 隆昌市 | F22: 小学 | G22: 该案例已在本校四年级美术课堂落地，具备大规模推广的成熟条件与广阔前景 | H22: 首创‘AI+IP主题+跨学科三维融合’教学范式，实现抽象知识可视化、互动化、跨学科融合，提升学生核心素养。 | I22: 需求分析 → 技术适配与定制 → 全流程应用实践与优化 → 应用迭代优化 | J22: ["动画建模", "动态转化", "语音合成", "互动答题系统", "3D虚拟展馆"] | K22: 剪映 | L22: 未点名企业 | M22: FALSE | N22: 软件平台 | O22: 教学辅助工具（工具型） | P22: 文档中提到‘融合Photoshop、剪映等工具，完成“丹尼”动画的修图与配音’ | Q22: 助学 | R22: 智能辅导系统 | S22: 美育 | T22: 学生：提升审美感知、艺术表现与文化理解能力；教师：实现跨学科教学的有效融合；学校：形成可复制的‘AI+学科’教学模式，推动基础教育智能化转型。 | U22: 需求分析 → 技术适配与定制 → 全流程应用实践与优化 → 应用迭代优化 | V22: 数据采集层（动态赋能模块、语音合成模块） 行为识别层（互动答题系统、知识认知场景化） 画像诊断层（虚拟展馆展示学生作品） | W22: 该案例已在本校四年级美术课堂落地，具备大规模推广的成熟条件与广阔前景，推动基础教育数字化转型。 | X22: 首创‘AI+IP主题+跨学科三维融合’教学范式，通过动态演示与虚拟展馆展示，打破学科壁垒，实现知识的可视化与互动化，提升学生的参与感与创作成就感。 | Y22: 美术 | Z22: 剪映AI | AA22: 深圳市脸萌科技有限公司 | AB22: 四川省 | AD22: =VLOOKUP($K22,「工具标准名」映射表!$B:$I,3,0) -> 剪映AI | AE22: =VLOOKUP($K22,「工具标准名」映射表!$B:$I,4,0) -> 功能应用层 | AF22: =VLOOKUP($K22,「工具标准名」映射表!$B:$I,5,0) -> 功能应用层（AI智能体） | AG22: =VLOOKUP($K22,「工具标准名」映射表!$B:$I,6,0) -> 软件工具 | AH22: =VLOOKUP($K22,「工具标准名」映射表!$B:$I,7,0) -> AI智能体 | AI22: =VLOOKUP($K22,「工具标准名」映射表!$B:$I,8,0) -> 是 | AJ22: 四川省
A23: 第12号案例_12重庆市第八中学校+从“动手实践”到“真实探究”：生成式AI支持下中学科学课程的五轮迭代研究.pdf | B23: 46056.455 | C23: 12 | D23: 从“动手实践”到“真实探究”：生成式AI支持下中学科学课程的五轮迭代研究 | E23: 重庆市 | F23: 初中 | G23: 已在重庆八中宏帆中学科学课程中完成连续五轮实践迭代，形成了较为成熟的协同成长框架，覆盖师生1200余人。 | H23: 构建了“教师—专家—AI—学生学习证据”协同成长框架，系统揭示了教师在专家指导与生成式AI支持下的课程迭代与专业成长路径，推动了课堂教学由“讲授—模仿”向“探究—共创”的转型。 | I23: 教师在专家指导与生成式AI支持下的五轮课程迭代过程 | J23: ["生成式人工智能", "学习设计优化", "动态反馈机制", "科学探究流程", "个性化支持"] | K23: DeepSeek | L23: 未点名企业 | M23: FALSE | N23: AI系统 | O23: AI 能力 / 模型 / API（基础层） | P23: 文档中提到“案例使用的基础大模型DeepSeek” | Q23: 助教 | R23: 教学分析 | S23: 智育 | T23: 学生：提升科学探究能力与创新意识；教师：实现教学设计优化与专业成长；学校：推动STEM教育的本土化发展与教育资源均衡。 | U23: 课程设计优化 → 教师反思与实践 → 生成式AI支持 → 学生探究与反馈 | V23: 数据采集层（学习过程记录、课堂实录） 行为识别层（学生探究行为分析） 画像诊断层（教师教学效果评估） 个性化学习层（AI辅助个性化探究路径） | W23: 企业产品以“AI辅助教学工具”为主，学校通过专家指导与AI支持实现教学适配，整体处于推广应用阶段。 | X23: 构建了“教师—专家—AI—学生学习证据”协同成长框架，系统揭示了教师在专家指导与生成式AI支持下的课程迭代与专业成长路径，推动了课堂教学由“讲授—模仿”向“探究—共创”的转型。 | Y23: 科学 | Z23: DeepSeek 大模型 | AA23: 杭州深度求索人工智能基础技术研究有限公司 | AB23: 重庆市 | AD23: =VLOOKUP($K23,「工具标准名」映射表!$B:$I,3,0) -> DeepSeek 大模型 | AE23: =VLOOKUP($K23,「工具标准名」映射表!$B:$I,4,0) -> 功能应用层 | AF23: =VLOOKUP($K23,「工具标准名」映射表!$B:$I,5,0) -> 功能应用（教学辅助工具） | AG23: =VLOOKUP($K23,「工具标准名」映射表!$B:$I,6,0) -> 软件工具 | AH23: =VLOOKUP($K23,「工具标准名」映射表!$B:$I,7,0) -> AI智能体 | AI23: =VLOOKUP($K23,「工具标准名」映射表!$B:$I,8,0) -> 否 | AJ23: 重庆市
A24: 第13号案例_13九原区第一实验小学 高嘉彤 “人工智能+基础教育”典型应用场景案例”.pdf | B24: 46056.456 | C24: 13 | D24: AI赋能课堂组织管理：助力《圆的周长》探究式教学 | E24: 九原区 | F24: 小学 | G24: 已在校内多个年级探究课中成功复制，具备极强的规模化推广潜力 | H24: 通过集成多种AI工具，构建高效、互动、数据驱动的智能教学环境，实现了从教师主导到学生数据驱动探究的教学模式转变。 | I24: 课堂导入视频生成 → 语音问答与AI编程互动 → 即时练习与反馈生成 → 数据可视化管理 | J24: ["语音识别", "AI编程", "数据分析", "即时反馈", "生成式AI"] | K24: 即梦AI | L24: 未点名企业 | M24: FALSE | N24: 软件平台 | O24: Web 教学平台（SaaS） | P24: 文档中提到“利用即梦AI生成课堂导入视频，提升学生的学习探究兴趣” | Q24: 助教 | R24: 课堂管理 | S24: 智育 | T24: 学生：提升课堂参与度与学习效率；教师：减轻数据统计负担，更专注于教学引导；学校：实现课堂组织管理的高效化与科学化。 | U24: 课堂导入视频生成 → 学生互动程序生成 → 实时反馈与评价 → 教学决策优化 | V24: 数据采集层（即时反馈数据采集与可视化管理） 行为识别层（学生参与度分析） 个性化学习层（即时生成反馈与评价） | W24: 该案例在基础教育领域处于积极探索阶段，利用轻量级AI工具实现课堂教学的数字化转型，具备较强的推广潜力。 | X24: 通过集成多种AI工具，实现了从传统教学模式向数据驱动探究式教学的转变，构建了低门槛的智能教学环境，提升了课堂参与率与反馈效率。 | Y24: 数学 | Z24: 即梦AI | AA24: 深圳市脸萌科技有限公司 | AB24: 内蒙古自治区 | AD24: =VLOOKUP($K24,「工具标准名」映射表!$B:$I,3,0) -> 即梦AI | AE24: =VLOOKUP($K24,「工具标准名」映射表!$B:$I,4,0) -> 功能应用层 | AF24: =VLOOKUP($K24,「工具标准名」映射表!$B:$I,5,0) -> 功能应用（生成式AI应用-图像类） | AG24: =VLOOKUP($K24,「工具标准名」映射表!$B:$I,6,0) -> 软件工具 | AH24: =VLOOKUP($K24,「工具标准名」映射表!$B:$I,7,0) -> AI智能体 | AI24: =VLOOKUP($K24,「工具标准名」映射表!$B:$I,8,0) -> 是 | AJ24: 内蒙古自治区
A25: 第13号案例_13九原区第一实验小学 高嘉彤 “人工智能+基础教育”典型应用场景案例”.pdf | B25: 46056.456 | C25: 13 | D25: AI赋能课堂组织管理：助力《圆的周长》探究式教学 | E25: 九原区 | F25: 小学 | G25: 已在校内多个年级探究课中成功复制，具备极强的规模化推广潜力 | H25: 通过集成多种AI工具，构建高效、互动、数据驱动的智能教学环境，实现了从教师主导到学生数据驱动探究的教学模式转变。 | I25: 课堂导入视频生成 → 语音问答与AI编程互动 → 即时练习与反馈生成 → 数据可视化管理 | J25: ["语音识别", "AI编程", "数据分析", "即时反馈", "生成式AI"] | K25: 豆包 | L25: 未点名企业 | M25: FALSE | N25: 软件平台 | O25: Web 教学平台（SaaS） | P25: 文档中描述“引入豆包的语音问答与AI编程功能，作为‘AI助教’” | Q25: 助教 | R25: 课堂管理 | S25: 智育 | T25: 学生：提升课堂参与度与学习效率；教师：减轻数据统计负担，更专注于教学引导；学校：实现课堂组织管理的高效化与科学化。 | U25: 课堂导入视频生成 → 学生互动程序生成 → 实时反馈与评价 → 教学决策优化 | V25: 数据采集层（即时反馈数据采集与可视化管理） 行为识别层（学生参与度分析） 个性化学习层（即时生成反馈与评价） | W25: 该案例在基础教育领域处于积极探索阶段，利用轻量级AI工具实现课堂教学的数字化转型，具备较强的推广潜力。 | X25: 通过集成多种AI工具，实现了从传统教学模式向数据驱动探究式教学的转变，构建了低门槛的智能教学环境，提升了课堂参与率与反馈效率。 | Y25: 数学 | Z25: 豆包 | AA25: 北京春田知韵科技有限公司 | AB25: 内蒙古自治区 | AD25: =VLOOKUP($K25,「工具标准名」映射表!$B:$I,3,0) -> 豆包 | AE25: =VLOOKUP($K25,「工具标准名」映射表!$B:$I,4,0) -> 功能应用层 | AF25: =VLOOKUP($K25,「工具标准名」映射表!$B:$I,5,0) -> 功能应用（教学辅助工具） | AG25: =VLOOKUP($K25,「工具标准名」映射表!$B:$I,6,0) -> 软件工具 | AH25: =VLOOKUP($K25,「工具标准名」映射表!$B:$I,7,0) -> 其他 | AI25: =VLOOKUP($K25,「工具标准名」映射表!$B:$I,8,0) -> 否 | AJ25: 内蒙古自治区
A26: 第13号案例_13九原区第一实验小学 高嘉彤 “人工智能+基础教育”典型应用场景案例”.pdf | B26: 46056.456 | C26: 13 | D26: AI赋能课堂组织管理：助力《圆的周长》探究式教学 | E26: 九原区 | F26: 小学 | G26: 已在校内多个年级探究课中成功复制，具备极强的规模化推广潜力 | H26: 通过集成多种AI工具，构建高效、互动、数据驱动的智能教学环境，实现了从教师主导到学生数据驱动探究的教学模式转变。 | I26: 课堂导入视频生成 → 语音问答与AI编程互动 → 即时练习与反馈生成 → 数据可视化管理 | J26: ["语音识别", "AI编程", "数据分析", "即时反馈", "生成式AI"] | K26: 问卷星 | L26: 未点名企业 | M26: FALSE | N26: 软件平台 | O26: Web 教学平台（SaaS） | P26: 文档中提到“使用问卷星AI，自动生成分层练习题，并创建在线答题卷” | Q26: 助教 | R26: 课堂管理 | S26: 智育 | T26: 学生：提升课堂参与度与学习效率；教师：减轻数据统计负担，更专注于教学引导；学校：实现课堂组织管理的高效化与科学化。 | U26: 课堂导入视频生成 → 学生互动程序生成 → 实时反馈与评价 → 教学决策优化 | V26: 数据采集层（即时反馈数据采集与可视化管理） 行为识别层（学生参与度分析） 个性化学习层（即时生成反馈与评价） | W26: 该案例在基础教育领域处于积极探索阶段，利用轻量级AI工具实现课堂教学的数字化转型，具备较强的推广潜力。 | X26: 通过集成多种AI工具，实现了从传统教学模式向数据驱动探究式教学的转变，构建了低门槛的智能教学环境，提升了课堂参与率与反馈效率。 | Y26: 数学 | Z26: 问卷星 | AA26: 0 | AB26: 内蒙古自治区 | AD26: =VLOOKUP($K26,「工具标准名」映射表!$B:$I,3,0) -> 问卷星 | AE26: =VLOOKUP($K26,「工具标准名」映射表!$B:$I,4,0) -> 功能应用层 | AF26: =VLOOKUP($K26,「工具标准名」映射表!$B:$I,5,0) -> 功能应用（Web 教学平台（SaaS）） | AG26: =VLOOKUP($K26,「工具标准名」映射表!$B:$I,6,0) -> 软件工具 | AH26: =VLOOKUP($K26,「工具标准名」映射表!$B:$I,7,0) -> AI智能体 | AI26: =VLOOKUP($K26,「工具标准名」映射表!$B:$I,8,0) -> 否 | AJ26: 内蒙古自治区
A27: 第14号案例_14铜梁中学 基于“AI+项目化”的铜梁中学“数项融合”校本课程的开发与应用实践(1026).pdf | B27: 46056.458 | C27: 14 | D27: 基于“AI+项目化”的铜梁中学“数项融合”高中物理校本课程的开发与应用实践 | E27: 重庆市 | F27: 高中 | G27: 铜梁中学已在多所高中实施，整体处于规模化推广阶段 | H27: 通过AI与项目化学习的结合，创新了高中物理教学模式，提升了学生的实践能力与创新能力。 | I27: AI辅助课堂教学与互动 → 虚拟实验与实践教学 → 智能学情诊断与个性化辅导 | J27: ["人工智能算法", "虚拟现实技术", "智能作业批改系统", "智能诊断系统", "项目化学习"] | K27: 国家智慧教育平台 | L27: 未点名企业 | M27: FALSE | N27: 平台型综合系统 | O27: 平台型综合系统 | P27: 文档中提到“以国家智慧教育平台为基础，整合校内外数字资源” | Q27: 助教 | R27: 智能辅导系统 | S27: 智育 | T27: 学生：提升实践能力与创新思维；教师：增强AI辅助教学能力；学校：推动课程改革与教学质量提升。 | U27: AI辅助课堂教学与互动 → 虚拟实验教学 → 智能学情诊断与个性化辅导 → 课程开发与应用 | V27: 数据采集层（多模态学习数据采集与融合） 行为识别层（学习意图识别、学习路径偏差检测） 画像诊断层（个性化画像生成、过程性反馈解释） 个性化学习层（即时生成反馈） | W27: 企业产品以“学习支持工具”为主，学校通过校本化规则实现教学适配，整体处于规模化应用初期。 | X27: 通过“AI+项目化”教学模式，构建了多元智慧学习场景，促进了物理教学的实践与创新，形成了鲜明的项目驱动与AI赋能特色。 | Y27: 物理 | Z27: 国家智慧教育平台 | AA27: 0 | AB27: 重庆市 | AD27: =VLOOKUP($K27,「工具标准名」映射表!$B:$I,3,0) -> 国家智慧教育平台 | AE27: =VLOOKUP($K27,「工具标准名」映射表!$B:$I,4,0) -> 教育数据层 | AF27: =VLOOKUP($K27,「工具标准名」映射表!$B:$I,5,0) -> 功能应用（Web 教学平台（SaaS）） | AG27: =VLOOKUP($K27,「工具标准名」映射表!$B:$I,6,0) -> 在线资源 | AH27: =VLOOKUP($K27,「工具标准名」映射表!$B:$I,7,0) -> 其他 | AI27: =VLOOKUP($K27,「工具标准名」映射表!$B:$I,8,0) -> 否 | AJ27: 重庆市
A28: 第14号案例_14铜梁中学 基于“AI+项目化”的铜梁中学“数项融合”校本课程的开发与应用实践(1026).pdf | B28: 46056.458 | C28: 14 | D28: 基于“AI+项目化”的铜梁中学“数项融合”高中物理校本课程的开发与应用实践 | E28: 重庆市 | F28: 高中 | G28: 铜梁中学已在多所高中实施，整体处于规模化推广阶段 | H28: 通过AI与项目化学习的结合，创新了高中物理教学模式，提升了学生的实践能力与创新能力。 | I28: AI辅助课堂教学与互动 → 虚拟实验与实践教学 → 智能学情诊断与个性化辅导 | J28: ["人工智能算法", "虚拟现实技术", "智能作业批改系统", "智能诊断系统", "项目化学习"] | K28: AI智能作业批改系统 | L28: 未点名企业 | M28: FALSE | N28: 软件平台 | O28: Web 教学平台（SaaS） | P28: 文档中描述“通过AI智能作业批改系统，智能诊断学生的物理学科薄弱知识点” | Q28: 助教 | R28: 智能辅导系统 | S28: 智育 | T28: 学生：提升实践能力与创新思维；教师：增强AI辅助教学能力；学校：推动课程改革与教学质量提升。 | U28: AI辅助课堂教学与互动 → 虚拟实验教学 → 智能学情诊断与个性化辅导 → 课程开发与应用 | V28: 数据采集层（多模态学习数据采集与融合） 行为识别层（学习意图识别、学习路径偏差检测） 画像诊断层（个性化画像生成、过程性反馈解释） 个性化学习层（即时生成反馈） | W28: 企业产品以“学习支持工具”为主，学校通过校本化规则实现教学适配，整体处于规模化应用初期。 | X28: 通过“AI+项目化”教学模式，构建了多元智慧学习场景，促进了物理教学的实践与创新，形成了鲜明的项目驱动与AI赋能特色。 | Y28: 物理 | Z28: AI智能作业批改系统 | AA28: 0 | AB28: 重庆市 | AD28: =VLOOKUP($K28,「工具标准名」映射表!$B:$I,3,0) -> AI智能作业批改系统 | AE28: =VLOOKUP($K28,「工具标准名」映射表!$B:$I,4,0) -> 功能应用层 | AF28: =VLOOKUP($K28,「工具标准名」映射表!$B:$I,5,0) -> 功能应用（教学辅助工具） | AG28: =VLOOKUP($K28,「工具标准名」映射表!$B:$I,6,0) -> 软件工具 | AH28: =VLOOKUP($K28,「工具标准名」映射表!$B:$I,7,0) -> 大语言模型 | AI28: =VLOOKUP($K28,「工具标准名」映射表!$B:$I,8,0) -> 是 | AJ28: 重庆市
A29: 第14号案例_14铜梁中学 基于“AI+项目化”的铜梁中学“数项融合”校本课程的开发与应用实践(1026).pdf | B29: 46056.458 | C29: 14 | D29: 基于“AI+项目化”的铜梁中学“数项融合”高中物理校本课程的开发与应用实践 | E29: 重庆市 | F29: 高中 | G29: 铜梁中学已在多所高中实施，整体处于规模化推广阶段 | H29: 通过AI与项目化学习的结合，创新了高中物理教学模式，提升了学生的实践能力与创新能力。 | I29: AI辅助课堂教学与互动 → 虚拟实验与实践教学 → 智能学情诊断与个性化辅导 | J29: ["人工智能算法", "虚拟现实技术", "智能作业批改系统", "智能诊断系统", "项目化学习"] | K29: DIS数字化实验平台 | L29: 未点名企业 | M29: FALSE | N29: 软件平台 | O29: Web 教学平台（SaaS） | P29: 文档中提到“利用DIS数字化实验平台和VR体验设备开展定量实验和定性实验” | Q29: 助教 | R29: 智能辅导系统 | S29: 智育 | T29: 学生：提升实践能力与创新思维；教师：增强AI辅助教学能力；学校：推动课程改革与教学质量提升。 | U29: AI辅助课堂教学与互动 → 虚拟实验教学 → 智能学情诊断与个性化辅导 → 课程开发与应用 | V29: 数据采集层（多模态学习数据采集与融合） 行为识别层（学习意图识别、学习路径偏差检测） 画像诊断层（个性化画像生成、过程性反馈解释） 个性化学习层（即时生成反馈） | W29: 企业产品以“学习支持工具”为主，学校通过校本化规则实现教学适配，整体处于规模化应用初期。 | X29: 通过“AI+项目化”教学模式，构建了多元智慧学习场景，促进了物理教学的实践与创新，形成了鲜明的项目驱动与AI赋能特色。 | Y29: 物理 | Z29: DIS数字化实验平台 | AA29: 0 | AB29: 重庆市 | AD29: =VLOOKUP($K29,「工具标准名」映射表!$B:$I,3,0) -> DIS数字化实验平台 | AE29: =VLOOKUP($K29,「工具标准名」映射表!$B:$I,4,0) -> 功能应用层 | AF29: =VLOOKUP($K29,「工具标准名」映射表!$B:$I,5,0) -> 功能应用（平台型综合系统） | AG29: =VLOOKUP($K29,「工具标准名」映射表!$B:$I,6,0) -> 软件工具 | AH29: =VLOOKUP($K29,「工具标准名」映射表!$B:$I,7,0) -> 其他 | AI29: =VLOOKUP($K29,「工具标准名」映射表!$B:$I,8,0) -> 否 | AJ29: 重庆市
A30: 第15号案例_15重庆市第八中学校+AI+SFK交互式人工智能教具应用与推广.pdf | B30: 46056.459 | C30: 15 | D30: AI+SFK交互式人工智能教具应用与推广 | E30: 重庆市 | F30: 初中 | G30: 已在重庆市50余所中小学应用验证，形成可复制的推广模式 | H30: 通过模块化设计和双面布局，降低了教学门槛，激发学生兴趣，培养计算思维与探究能力。 | I30: 需求分析 → 教具设计与研发 → 应用实践与反馈优化 → 推广与应用 | J30: ["模块化设计", "传感器与执行机构集成", "项目式教学资源开发", "跨学科融合学习", "用户体验优化"] | K30: AI+SFK交互式人工智能教具 | L30: 未点名企业 | M30: TRUE | N30: 硬件 + 教学资源 | O30: 教学辅助工具（工具型） | P30: 文档中提到“本案例研发了AI+SFK交互式人工智能教具及配套课程体系” | Q30: 助教 | R30: 教学辅助 | S30: 智育 | T30: 学生：激发对人工智能的兴趣，培养计算思维与探究能力；教师：降低教学门槛，提高教学效率；学校：形成可复制、可推广的AI教育新模式。 | U30: 需求分析 → 教具设计与开发 → 应用实践与反馈 → 持续优化与推广 | V30: 理念创新（可触摸的思维）；结构创新（模块化集成）；外观创新（双面布局）；资源创新（项目式教学资源库） | W30: 已在重庆市50余所中小学推广应用，整体处于规模化应用阶段，形成了“本校-集团-区域”三级推广网络。 | X30: 通过软硬件协同、简化操作、双面布局等创新，实现了从传统编程到理解底层逻辑的跨越，提升了教学的互动性与趣味性。 | Y30: 人工智能 | Z30: AI+SFK交互式人工智能教具 | AA30: 0 | AB30: 重庆市 | AD30: =VLOOKUP($K30,「工具标准名」映射表!$B:$I,3,0) -> AI+SFK交互式人工智能教具 | AE30: =VLOOKUP($K30,「工具标准名」映射表!$B:$I,4,0) -> 功能应用层 | AF30: =VLOOKUP($K30,「工具标准名」映射表!$B:$I,5,0) -> 功能应用（教学辅助工具） | AG30: =VLOOKUP($K30,「工具标准名」映射表!$B:$I,6,0) -> 硬件设备 | AH30: =VLOOKUP($K30,「工具标准名」映射表!$B:$I,7,0) -> AI智能体 | AI30: =VLOOKUP($K30,「工具标准名」映射表!$B:$I,8,0) -> 否 | AJ30: 重庆市
A31: 第16号案例_16重庆市人民小学校 革新发展性评价 培育“五星好少年”-申报书.pdf | B31: 46056.461 | C31: 16 | D31: 革新发展性评价 培育“五星好少年” | E31: 重庆市 | F31: 小学 | G31: 已在重庆市人民小学教育集团全面应用，形成可复制的评价体系与技术平台 | H31: 通过建立综合评价指标体系与个性化成长档案，实现学生评价从结果判断向过程赋能的转变，推动德智体美劳全面发展。 | I31: 建立综合评价指标体系 → 引入数字技术建立评价技术系统 → 生成个性化成长档案 → 实现精准赋能 | J31: ["多模态数据融合", "人工智能算法", "物联网技术", "数据可视化", "智能评价系统"] | K31: 劳动萌主小程序 | L31: 未点名企业 | M31: TRUE | N31: 软件平台 | O31: Web 教学平台（SaaS） | P31: 文档中提到“自主研发‘劳动萌主’小程序，打通劳动任务发布、过程记录、多方评价、徽章激励全流程。” | Q31: 助评 | R31: 综合素质评价 | S31: 德智体美劳 | T31: 学生：全面发展、个性化成长；教师：减轻评价负担、精准指导；学校：提升育人效能、获得多项荣誉 | U31: 数据采集 → 评价体系构建 → 个性化成长档案生成 → 过程赋能 | V31: 数据采集层（多模态数据采集与融合） 行为识别层（学生表现实时评价） 画像诊断层（个性化成长画像生成） | W31: 案例已在重庆市人民小学教育集团全面应用，形成可复制的实施方案，具有显著的社会效益与人才发展价值 | X31: 创新性地将物联网数据采集与人工智能算法深度整合，形成全流程技术解决方案，实现综合性、过程性的学生评价的规模化、常态化实施 | Y31: 未提及 | Z31: 劳动萌主小程序 | AA31: 0 | AB31: 重庆市 | AD31: =VLOOKUP($K31,「工具标准名」映射表!$B:$I,3,0) -> 劳动萌主小程序 | AE31: =VLOOKUP($K31,「工具标准名」映射表!$B:$I,4,0) -> 功能应用层 | AF31: =VLOOKUP($K31,「工具标准名」映射表!$B:$I,5,0) -> 功能应用（Web 教学平台（SaaS）） | AG31: =VLOOKUP($K31,「工具标准名」映射表!$B:$I,6,0) -> 软件工具 | AH31: =VLOOKUP($K31,「工具标准名」映射表!$B:$I,7,0) -> AI智能体 | AI31: =VLOOKUP($K31,「工具标准名」映射表!$B:$I,8,0) -> 否 | AJ31: 重庆市
A32: 第16号案例_16重庆市人民小学校 革新发展性评价 培育“五星好少年”-申报书.pdf | B32: 46056.461 | C32: 16 | D32: 革新发展性评价 培育“五星好少年” | E32: 重庆市 | F32: 小学 | G32: 已在重庆市人民小学教育集团全面应用，形成可复制的评价体系与技术平台 | H32: 通过建立综合评价指标体系与个性化成长档案，实现学生评价从结果判断向过程赋能的转变，推动德智体美劳全面发展。 | I32: 建立综合评价指标体系 → 引入数字技术建立评价技术系统 → 生成个性化成长档案 → 实现精准赋能 | J32: ["多模态数据融合", "人工智能算法", "物联网技术", "数据可视化", "智能评价系统"] | K32: 云师智学 | L32: 未点名企业 | M32: FALSE | N32: 软件平台 | O32: 平台型综合系统 | P32: 文档中提到“依托云师智学、班级优化大师等智慧平台，教师采集学生课堂、作业、考试等全链条数据。” | Q32: 助评 | R32: 综合素质评价 | S32: 德智体美劳 | T32: 学生：全面发展、个性化成长；教师：减轻评价负担、精准指导；学校：提升育人效能、获得多项荣誉 | U32: 数据采集 → 评价体系构建 → 个性化成长档案生成 → 过程赋能 | V32: 数据采集层（多模态数据采集与融合） 行为识别层（学生表现实时评价） 画像诊断层（个性化成长画像生成） | W32: 案例已在重庆市人民小学教育集团全面应用，形成可复制的实施方案，具有显著的社会效益与人才发展价值 | X32: 创新性地将物联网数据采集与人工智能算法深度整合，形成全流程技术解决方案，实现综合性、过程性的学生评价的规模化、常态化实施 | Y32: 未提及 | Z32: 云师智学 | AA32: 0 | AB32: 重庆市 | AD32: =VLOOKUP($K32,「工具标准名」映射表!$B:$I,3,0) -> 云师智学 | AE32: =VLOOKUP($K32,「工具标准名」映射表!$B:$I,4,0) -> 功能应用层 | AF32: =VLOOKUP($K32,「工具标准名」映射表!$B:$I,5,0) -> 功能应用（校级 / 区域级系统） | AG32: =VLOOKUP($K32,「工具标准名」映射表!$B:$I,6,0) -> 软件工具 | AH32: =VLOOKUP($K32,「工具标准名」映射表!$B:$I,7,0) -> AI智能体 | AI32: =VLOOKUP($K32,「工具标准名」映射表!$B:$I,8,0) -> 否 | AJ32: 重庆市
A33: 第16号案例_16重庆市人民小学校 革新发展性评价 培育“五星好少年”-申报书.pdf | B33: 46056.461 | C33: 16 | D33: 革新发展性评价 培育“五星好少年” | E33: 重庆市 | F33: 小学 | G33: 已在重庆市人民小学教育集团全面应用，形成可复制的评价体系与技术平台 | H33: 通过建立综合评价指标体系与个性化成长档案，实现学生评价从结果判断向过程赋能的转变，推动德智体美劳全面发展。 | I33: 建立综合评价指标体系 → 引入数字技术建立评价技术系统 → 生成个性化成长档案 → 实现精准赋能 | J33: ["多模态数据融合", "人工智能算法", "物联网技术", "数据可视化", "智能评价系统"] | K33: 量子大健康云平台 | L33: 未点名企业 | M33: FALSE | N33: 软件平台 | O33: 平台型综合系统 | P33: 文档中提到“建设‘量子大健康云平台’，开展三年周期的体质监测与动态干预。” | Q33: 助评 | R33: 综合素质评价 | S33: 德智体美劳 | T33: 学生：全面发展、个性化成长；教师：减轻评价负担、精准指导；学校：提升育人效能、获得多项荣誉 | U33: 数据采集 → 评价体系构建 → 个性化成长档案生成 → 过程赋能 | V33: 数据采集层（多模态数据采集与融合） 行为识别层（学生表现实时评价） 画像诊断层（个性化成长画像生成） | W33: 案例已在重庆市人民小学教育集团全面应用，形成可复制的实施方案，具有显著的社会效益与人才发展价值 | X33: 创新性地将物联网数据采集与人工智能算法深度整合，形成全流程技术解决方案，实现综合性、过程性的学生评价的规模化、常态化实施 | Y33: 未提及 | Z33: 量子大健康云平台 | AA33: 0 | AB33: 重庆市 | AD33: =VLOOKUP($K33,「工具标准名」映射表!$B:$I,3,0) -> 量子大健康云平台 | AE33: =VLOOKUP($K33,「工具标准名」映射表!$B:$I,4,0) -> 功能应用层 | AF33: =VLOOKUP($K33,「工具标准名」映射表!$B:$I,5,0) -> 功能应用（平台型综合系统） | AG33: =VLOOKUP($K33,「工具标准名」映射表!$B:$I,6,0) -> 软件工具 | AH33: =VLOOKUP($K33,「工具标准名」映射表!$B:$I,7,0) -> AI智能体 | AI33: =VLOOKUP($K33,「工具标准名」映射表!$B:$I,8,0) -> 否 | AJ33: 重庆市
A34: 第17号案例_17重庆市第八中学校+AI+校园全域智学成长平台.pdf | B34: 46056.463 | C34: 17 | D34: AI+校园全域智学成长平台 | E34: 重庆市 | F34: 高中 | G34: 已在重庆市部分区县高中成功落地，验证了其低成本、高效益的规模化推广潜力。 | H34: 通过构建全量数据融合的精准教学新范式，打破数据孤岛，实现动态学情画像与个性化教学干预，显著提升教学质量与效率。 | I34: 数据采集与分析 → 动态学情画像构建 → 精准教学干预 → 学习路径优化 | J34: ["数据治理", "动态学情画像", "智能批改", "个性化学习规划", "多模型联合调度"] | K34: AI+校园全域智学成长平台 | L34: 重庆智学慧阅科技有限责任公司 | M34: TRUE | N34: 软件平台 | O34: 平台型综合系统 | P34: 文档中提到“打造‘AI+校园全域智学成长平台’，以全域数据采集与分析为基础” | Q34: 助学 | R34: 智能学情诊断与个性化辅导 | S34: 智育 | T34: 学生：实现个性化学习规划，提升学习效率与信心；教师：减轻批改负担，提升教学质量；学校：构建公平优质的教育新生态。 | U34: 数据采集 → 动态学情画像构建 → 精准教学干预 → 个性化学习路径优化 | V34: 数据采集层（动态学情画像构建） 行为识别层（学生思维路径与认知负荷分析） 画像诊断层（多维动态学生能力画像） 智能策略层（个性化学习路径推荐） | W34: 企业产品以“学习支持工具”为主，已在重庆市部分区县高中成功落地，具备低成本、高效益的规模化推广潜力。 | X34: 重构基于全量数据融合的精准教学新范式，打破数据孤岛，实现动态能力画像与个性化教学干预，提升教学质量与效率。 | Y34: 未提及 | Z34: AI+校园全域智学成长平台 | AA34: 0 | AB34: 重庆市 | AD34: =VLOOKUP($K34,「工具标准名」映射表!$B:$I,3,0) -> AI+校园全域智学成长平台 | AE34: =VLOOKUP($K34,「工具标准名」映射表!$B:$I,4,0) -> 功能应用层 | AF34: =VLOOKUP($K34,「工具标准名」映射表!$B:$I,5,0) -> 功能应用（校级 / 区域级系统） | AG34: =VLOOKUP($K34,「工具标准名」映射表!$B:$I,6,0) -> 软件工具 | AH34: =VLOOKUP($K34,「工具标准名」映射表!$B:$I,7,0) -> 其他 | AI34: =VLOOKUP($K34,「工具标准名」映射表!$B:$I,8,0) -> 是 | AJ34: 重庆市
A35: 第18号案例_18重庆市第八中学校+AI赋能教育评价创新——基于三创教育理念的任务链与成长画像实践.pdf | B35: 46056.464 | C35: 18 | D35: AI赋能教育评价创新——基于三创教育理念的任务链与成长画像实践 | E35: 重庆市 | F35: 初中 | G35: 本案例已在多个年级常态化实施，显著提升了教师诊断教学能力与学生的学习主动性，推动“教、学、评”一体化改革，为AI赋能教育评价提供了可复制的路径与模型。 | H35: 通过AI技术实现学习行为采集、学习过程分析、成长画像生成与个性化反馈闭环，促进评价从“选拔工具”变为“学习引擎”，让学生在评价中学习、在反馈中成长。 | I35: 数据采集 → 智能分析 → 成长画像生成 → 反馈与应用 | J35: ["自然语言理解", "模式识别算法", "多模态数据采集", "个性化反馈", "动态评价"] | K35: YEEAI系统 | L35: 北京易知简教育科技有限公司 | M35: TRUE | N35: 软件平台 | O35: 平台型综合系统 | P35: 文档中提到“通过北京易知简教育科技有限公司研发的YEEAI系统，构建以‘任务链驱动、多源数据采集、成长画像反馈’为核心的形成性评价体系” | Q35: 助评 | R35: 学生成长数据分析与预警 | S35: 智育 | T35: 学生：提升学习主动性与自我反思能力；教师：增强精准教学能力；学校：推动‘教、学、评’一体化改革，形成可复制的教育评价创新路径。 | U35: 学习行为采集 → 学习过程分析 → 成长画像生成 → 个性化反馈 | V35: 数据采集层（多模态行为数据自动采集） 智能分析层（自然语言理解与模式识别算法） 画像诊断层（个体发展曲线与班级群体分析生成） 反馈与应用层（项目实施报告与个人成长画像查看） | W35: 企业产品以‘教育评价工具’为主，学校通过校企合作实现教学适配，整体处于规模化应用初期。 | X35: 构建AI支持的任务链学习模式，实现动态评价与个性化反馈，促进教师与学生的双向赋能，形成‘理念引领、技术支撑、场景共建’的协同创新机制。 | Y35: 未提及 | Z35: YEEAI系统 | AA35: 0 | AB35: 重庆市 | AD35: =VLOOKUP($K35,「工具标准名」映射表!$B:$I,3,0) -> YEEAI系统 | AE35: =VLOOKUP($K35,「工具标准名」映射表!$B:$I,4,0) -> 功能应用层 | AF35: =VLOOKUP($K35,「工具标准名」映射表!$B:$I,5,0) -> 功能应用（平台型综合系统） | AG35: =VLOOKUP($K35,「工具标准名」映射表!$B:$I,6,0) -> 软件工具 | AH35: =VLOOKUP($K35,「工具标准名」映射表!$B:$I,7,0) -> AI智能体 | AI35: =VLOOKUP($K35,「工具标准名」映射表!$B:$I,8,0) -> 否 | AJ35: 重庆市
A36: 第19号案例_19重庆市第八中学校+互动艺术与机器人社团综合互评系统.pdf | B36: 46056.465 | C36: 19 | D36: 互动艺术与机器人社团综合互评系统 | E36: 重庆市 | F36: 初中 | G36: 该项目自2025年初以来，目前已稳定服务2届学生，处于推广阶段 | H36: 通过多源数据融合分析，构建多维度标准化评价体系，提升评价深度与准确性，形成可复制的‘多主体互评’操作规范。 | I36: 数据收集与整合 → 多源数据分析 → 个性化综合评估 → 生成可视化发展报告 | J36: ["自然语言处理", "数据融合分析", "情感倾向分析", "能力维度评价", "团队协作能力评估"] | K36: 互动艺术与机器人社团综合互评系统 | L36: 未点名企业 | M36: TRUE | N36: 软件平台 | O36: 平台型综合系统 | P36: 文档中提到‘利用豆包大模型创建了“互动艺术与机器人社团综合互评系统”智能体作为整个评价体系的载体’ | Q36: 助学 | R36: 学生成长数据分析与预警 | S36: 智育 | T36: 学生：提供个性化综合评估与提升建议；教师：依据数据支撑定制教学方案；学校：提升社团在国际赛事中的竞争力。 | U36: 数据收集 → 多源数据融合分析 → 个性化综合评估 → 可视化发展报告生成 | V36: 数据采集层（多源数据整合与记录） 行为识别层（学生互评与教师评价分析） 画像诊断层（综合素质与能力评估生成） | W36: 项目已稳定服务2届学生，具备快速复制至其他实践性社团的潜力，整体处于推广阶段。 | X36: 构建了基于AI的多维度标准化评价体系，首次将学生互评与跨队互评纳入综合素质评价，提升了评价的客观性与准确性。 | Y36: 科技 | Z36: 互动艺术与机器人社团综合互评系统 | AA36: 0 | AB36: 重庆市 | AD36: =VLOOKUP($K36,「工具标准名」映射表!$B:$I,3,0) -> 互动艺术与机器人社团综合互评系统 | AE36: =VLOOKUP($K36,「工具标准名」映射表!$B:$I,4,0) -> 功能应用层 | AF36: =VLOOKUP($K36,「工具标准名」映射表!$B:$I,5,0) -> 功能应用（Web 教学平台（SaaS）） | AG36: =VLOOKUP($K36,「工具标准名」映射表!$B:$I,6,0) -> 软件工具 | AH36: =VLOOKUP($K36,「工具标准名」映射表!$B:$I,7,0) -> 其他 | AI36: =VLOOKUP($K36,「工具标准名」映射表!$B:$I,8,0) -> 否 | AJ36: 重庆市
A37: 第20号案例_20成都市泡桐树小学境界分校 AI赋能学生评价创新实践——“六度育人图谱”驱动的全场景综合素质发展体系构建.docx | B37: 46056.465 | C37: 20 | D37: AI赋能学生评价创新实践——“六度育人图谱”驱动的全场景综合素质发展体系构建 | E37: 成都市 | F37: 小学 | G37: 案例已实现全校全覆盖，成效显著，具备极强的可复制性 | H37: 实现了‘技术 - 课堂 - 生活’的深度融合创新，推动教育教学模式从‘单向评价’向‘协同共育’转变，建立了‘评价—诊断—改进—提升’的良性循环路径。 | I37: 理念转化 → 技术落地 → 场景应用 → 优化迭代 | J37: ["数据采集", "语音识别", "图像识别", "机器学习算法", "大数据分析"] | K37: AI成长学生发展平台 | L37: 未点名企业 | M37: TRUE | N37: 软件平台 | O37: 平台型综合系统 | P37: 文档中提到‘自主研发“AI成长学生发展平台”，构建“1个核心平台+2大应用场景+3维联动机制”生态体系’ | Q37: 助评 | R37: 综合素质评价 | S37: 德育 | T37: 学生：全面发展素质提升；教师：提高评价效率与精准度；学校：形成可复制的评价体系与管理模式。 | U37: 理念转化 → 技术落地 → 场景应用 → 优化迭代 | V37: 数据采集层（多终端设备与智能识别技术实现全场景数据采集） 行为识别层（AI实时捕捉学生状态与表现） 画像诊断层（生成学生成长树与班级素养雷达图） | W37: 案例已实现全校全覆盖，具备极强的可复制性，整体处于规模化应用初期 | X37: 实现了“技术 - 课堂 - 生活”的深度融合创新，打破传统教研局限，提升评价效率与精准度，推动教育教学模式从“单向评价”向“协同共育”转变。 | Y37: 未提及 | Z37: AI成长学生发展平台 | AA37: 0 | AB37: 四川省 | AD37: =VLOOKUP($K37,「工具标准名」映射表!$B:$I,3,0) -> AI成长学生发展平台 | AE37: =VLOOKUP($K37,「工具标准名」映射表!$B:$I,4,0) -> 功能应用层 | AF37: =VLOOKUP($K37,「工具标准名」映射表!$B:$I,5,0) -> 功能应用（校级 / 区域级系统） | AG37: =VLOOKUP($K37,「工具标准名」映射表!$B:$I,6,0) -> 软件工具 | AH37: =VLOOKUP($K37,「工具标准名」映射表!$B:$I,7,0) -> AI智能体 | AI37: =VLOOKUP($K37,「工具标准名」映射表!$B:$I,8,0) -> 否 | AJ37: 四川省
... A43: 第23号案例_23人工智能+基础教育”典型应用场景案例申报书(天台岗万国城小学).pdf | B43: 46056.465 | C43: 23 | D43: 生成式AI+知识图谱支持的小学生个性化学习路径构建与实践 | E43: 重庆市南岸区 | F43: 小学 | G43: 已在学校两个年级中的8个班开展常态化应用，整体处于规模化推广阶段 | H43: 通过生成式AI与知识图谱的结合，实现个性化学习路径的动态生成与实时反馈，提升学生自主学习能力与教学效率。 | I43: 生成式AI工具生成学情诊断报告 → 知识图谱构建与关联关系推送 → 实时反馈与个性化学习路径推荐 | J43: ["生成式AI", "知识图谱", "学习路径推荐算法", "智能体伴学系统", "数据分析"] | K43: 智能体伴学系统 | L43: 未点名企业 | M43: FALSE | N43: 软件平台 | O43: 平台型综合系统 | P43: 文档中提到“利用生成式AI实现学习清单的自动生成，利用智能体开展作业智能批改与个性化答疑” | Q43: 助学 | R43: 智能辅导系统 | S43: 智育 | T43: 学生：提升自主学习能力与个性化学习效果；教师：提高备课效率与精准教学能力；学校：形成可复制的个性化学习实践模式。 | U43: 生成式AI工具生成学情诊断报告 → 知识图谱构建与资源推送 → 实时反馈与个性化学习闭环 | V43: 数据采集层（动态生成学情诊断报告、知识图谱构建） 画像诊断层（个性化学习路径推荐、实时反馈机制） 个性化学习层（智能体伴学与个性化辅导） | W43: 企业产品以“支持个性化学习”为主，学校通过校本化规则实现教学适配，整体处于规模化应用初期。 | X43: 构建了“三层三阶”的个性化学习模型，突破传统教学模式，实现从“教为中心”向“学为中心”的转型，形成完整的学习阶段闭环。 | Y43: 语文、数学 | Z43: 智能体伴学系统 | AA43: 0 | AB43: 重庆市 | AD43: =VLOOKUP($K43,「工具标准名」映射表!$B:$I,3,0) -> 智能体伴学系统 | AE43: =VLOOKUP($K43,「工具标准名」映射表!$B:$I,4,0) -> 功能应用层 | AF43: =VLOOKUP($K43,「工具标准名」映射表!$B:$I,5,0) -> 功能应用（校级 / 区域级系统） | AG43: =VLOOKUP($K43,「工具标准名」映射表!$B:$I,6,0) -> 软件工具 | AH43: =VLOOKUP($K43,「工具标准名」映射表!$B:$I,7,0) -> AI智能体 | AI43: =VLOOKUP($K43,「工具标准名」映射表!$B:$I,8,0) -> 否 | AJ43: 重庆市
A44: 第24号案例_24北京十一学校顺义学校（杨镇一中）丁洁 指数衰减模型的跨学科探索——AI辅助下的核污水放射性衰变分析.docx | B44: 46056.465 | C44: 24 | D44: 指数衰减模型的跨学科探索——AI辅助下的核污水放射性衰变分析 | E44: 北京 | F44: 高中 | G44: 该模式已显示出提升课堂效率、深化学生探究能力的明确效果，通过教师培训即可快速规模化应用。 | H44: 案例成功地将数学、物理、社会热点及科技伦理融为一体，体现了STEM教育和项目式学习的核心思想，凸显了数学在解决真实世界问题中的价值。 | I44: 数据整合与精准学情分析 → 动态探究与高效互动 → 拓展探究与能力培养 | J44: ["数据分析", "动态数学软件", "AI工具", "模型构建", "批判性思维"] | K44: 豆包 | L44: 未点名企业 | M44: FALSE | N44: 软件平台 | O44: Web 教学平台（SaaS） | P44: 文档中提到“学生遇到如‘贝克勒尔单位’等即时性问题，可通过豆包等工具快速获得解答” | Q44: 助学 | R44: 智能辅导系统 | S44: 智育 | T44: 学生：提升高阶思维能力、科学素养与批判性思维；教师：实现精准备课与教学；学校：推动跨学科项目式学习的实施。 | U44: 数据整合与精准学情分析 → 动态探究与高效互动 → 拓展探究与能力培养 | V44: 数据采集层（跨学科数据整合、实时半衰期数据获取） 行为识别层（学情分析与反馈） 个性化学习层（AI工具辅助学习与资源推荐） | W44: 案例展示了AI技术在基础教育中的系统性应用，推动了跨学科教学的探索与实践，整体处于推广阶段。 | X44: 通过真实社会问题驱动，整合数学、物理与环境科学，利用AI工具提升学生的自主探究能力与批判性思维，体现了STEM教育与项目式学习的核心思想。 | Y44: 数学/物理/环境科学 | Z44: 豆包 | AA44: 北京春田知韵科技有限公司 | AB44: 北京市 | AD44: =VLOOKUP($K44,「工具标准名」映射表!$B:$I,3,0) -> 豆包 | AE44: =VLOOKUP($K44,「工具标准名」映射表!$B:$I,4,0) -> 功能应用层 | AF44: =VLOOKUP($K44,「工具标准名」映射表!$B:$I,5,0) -> 功能应用（教学辅助工具） | AG44: =VLOOKUP($K44,「工具标准名」映射表!$B:$I,6,0) -> 软件工具 | AH44: =VLOOKUP($K44,「工具标准名」映射表!$B:$I,7,0) -> 其他 | AI44: =VLOOKUP($K44,「工具标准名」映射表!$B:$I,8,0) -> 否 | AJ44: 北京市
A45: 第24号案例_24北京十一学校顺义学校（杨镇一中）丁洁 指数衰减模型的跨学科探索——AI辅助下的核污水放射性衰变分析.docx | B45: 46056.465 | C45: 24 | D45: 指数衰减模型的跨学科探索——AI辅助下的核污水放射性衰变分析 | E45: 北京 | F45: 高中 | G45: 该模式已显示出提升课堂效率、深化学生探究能力的明确效果，通过教师培训即可快速规模化应用。 | H45: 案例成功地将数学、物理、社会热点及科技伦理融为一体，体现了STEM教育和项目式学习的核心思想，凸显了数学在解决真实世界问题中的价值。 | I45: 数据整合与精准学情分析 → 动态探究与高效互动 → 拓展探究与能力培养 | J45: ["数据分析", "动态数学软件", "AI工具", "模型构建", "批判性思维"] | K45: Deepseek | L45: 未点名企业 | M45: FALSE | N45: 软件平台 | O45: Web 教学平台（SaaS） | P45: 文档中提到“学生利用AI工具（如豆包、Deepseek）快速搜集跨学科数据” | Q45: 助学 | R45: 智能辅导系统 | S45: 智育 | T45: 学生：提升高阶思维能力、科学素养与批判性思维；教师：实现精准备课与教学；学校：推动跨学科项目式学习的实施。 | U45: 数据整合与精准学情分析 → 动态探究与高效互动 → 拓展探究与能力培养 | V45: 数据采集层（跨学科数据整合、实时半衰期数据获取） 行为识别层（学情分析与反馈） 个性化学习层（AI工具辅助学习与资源推荐） | W45: 案例展示了AI技术在基础教育中的系统性应用，推动了跨学科教学的探索与实践，整体处于推广阶段。 | X45: 通过真实社会问题驱动，整合数学、物理与环境科学，利用AI工具提升学生的自主探究能力与批判性思维，体现了STEM教育与项目式学习的核心思想。 | Y45: 数学/物理/环境科学 | Z45: DeepSeek 大模型 | AA45: 杭州深度求索人工智能基础技术研究有限公司 | AB45: 北京市 | AD45: =VLOOKUP($K45,「工具标准名」映射表!$B:$I,3,0) -> DeepSeek 大模型 | AE45: =VLOOKUP($K45,「工具标准名」映射表!$B:$I,4,0) -> 功能应用层 | AF45: =VLOOKUP($K45,「工具标准名」映射表!$B:$I,5,0) -> 功能应用（教学辅助工具） | AG45: =VLOOKUP($K45,「工具标准名」映射表!$B:$I,6,0) -> 软件工具 | AH45: =VLOOKUP($K45,「工具标准名」映射表!$B:$I,7,0) -> AI智能体 | AI45: =VLOOKUP($K45,「工具标准名」映射表!$B:$I,8,0) -> 否 | AJ45: 北京市
A46: 第24号案例_24北京十一学校顺义学校（杨镇一中）丁洁 指数衰减模型的跨学科探索——AI辅助下的核污水放射性衰变分析.docx | B46: 46056.465 | C46: 24 | D46: 指数衰减模型的跨学科探索——AI辅助下的核污水放射性衰变分析 | E46: 北京 | F46: 高中 | G46: 该模式已显示出提升课堂效率、深化学生探究能力的明确效果，通过教师培训即可快速规模化应用。 | H46: 案例成功地将数学、物理、社会热点及科技伦理融为一体，体现了STEM教育和项目式学习的核心思想，凸显了数学在解决真实世界问题中的价值。 | I46: 数据整合与精准学情分析 → 动态探究与高效互动 → 拓展探究与能力培养 | J46: ["数据分析", "动态数学软件", "AI工具", "模型构建", "批判性思维"] | K46: GeoGebra | L46: 未点名企业 | M46: FALSE | N46: 软件平台 | O46: Web 教学平台（SaaS） | P46: 文档中提到“利用GeoGebra动态数学软件绘制指数函数图像” | Q46: 助学 | R46: 智能辅导系统 | S46: 智育 | T46: 学生：提升高阶思维能力、科学素养与批判性思维；教师：实现精准备课与教学；学校：推动跨学科项目式学习的实施。 | U46: 数据整合与精准学情分析 → 动态探究与高效互动 → 拓展探究与能力培养 | V46: 数据采集层（跨学科数据整合、实时半衰期数据获取） 行为识别层（学情分析与反馈） 个性化学习层（AI工具辅助学习与资源推荐） | W46: 案例展示了AI技术在基础教育中的系统性应用，推动了跨学科教学的探索与实践，整体处于推广阶段。 | X46: 通过真实社会问题驱动，整合数学、物理与环境科学，利用AI工具提升学生的自主探究能力与批判性思维，体现了STEM教育与项目式学习的核心思想。 | Y46: 数学/物理/环境科学 | Z46: GeoGebra | AA46: 0 | AB46: 北京市 | AD46: =VLOOKUP($K46,「工具标准名」映射表!$B:$I,3,0) -> GeoGebra | AE46: =VLOOKUP($K46,「工具标准名」映射表!$B:$I,4,0) -> 功能应用层 | AF46: =VLOOKUP($K46,「工具标准名」映射表!$B:$I,5,0) -> 功能应用（平台型综合系统） | AG46: =VLOOKUP($K46,「工具标准名」映射表!$B:$I,6,0) -> 软件工具 | AH46: =VLOOKUP($K46,「工具标准名」映射表!$B:$I,7,0) -> 其他 | AI46: =VLOOKUP($K46,「工具标准名」映射表!$B:$I,8,0) -> 否 | AJ46: 北京市
...

Sheet 省份产品
A1: 文件名 | B1: 工具标准名 | C1: 省份
A2: 第01号案例_1温州市新田园小学 叶诗婧《数“算”生“动”：AI赋能下运算律教学的新样态》.pdf | B2: AI学习机 | C2: 浙江省
A3: 第01号案例_1温州市新田园小学 叶诗婧《数“算”生“动”：AI赋能下运算律教学的新样态》.pdf | B3: AI语音互动平台 | C3: 浙江省
A4: 第01号案例_1温州市新田园小学 叶诗婧《数“算”生“动”：AI赋能下运算律教学的新样态》.pdf | B4: 动态点子图生成系统 | C4: 浙江省
A5: 第02号案例_2温州市新田园小学朱朝炜《三维联动：人工智能视域下小学足球运球游戏设计与研究》.pdf | B5: 智慧手环 | C5: 浙江省
A6: 第02号案例_2温州市新田园小学朱朝炜《三维联动：人工智能视域下小学足球运球游戏设计与研究》.pdf | B6: AI分析系统 | C6: 浙江省
A7: 第03号案例_3【案例】从赋能到内生：智能评测驱动“教学评一致”的机理与路径探寻.pdf | B7: 易点慧AI | C7: 浙江省
A8: 第04号案例_AI赋能地理课堂——七大洲轮廓记忆消消乐申报书.docx | B8: 七大洲速记挑战 | C8: 重庆市
A9: 第07号案例_案例申报书.docx | B9: DeepSeek 大模型 | C9: 重庆市
A10: 第07号案例_案例申报书.docx | B10: 可灵AI | C10: 重庆市
A11: 第07号案例_案例申报书.docx | B11: 豆包 | C11: 重庆市
A12: 第08号案例_8川外科中-《AI智教分析：教学相长的协同创新》案例.docx | B12: 未来教室 | C12: 重庆市
... A100: 第62号案例_（冯怡）人工智能+基础教育案例.docx | B100: AI智批系统 | C100: 浙江省
A101: 第63号案例_“人工智能+基础教育”典型案例申报表.pdf | B101: #N/A | C101: 未提及
A102: 第64号案例_人工智能+作业批改 典型应用场景案例.docx | B102: 蜜蜂家校 | C102: 河北省
A103: 第65号案例_成都七中初中附属小学+数智赋能小学作业治理：精准画像与个性化.docx | B103: AI学情分析平台 | C103: 四川省
A104: 第65号案例_成都七中初中附属小学+数智赋能小学作业治理：精准画像与个性化.docx | B104: AI点阵笔 | C104: 四川省
A105: 第66号案例_成都东部新区第七中学校（成都七中东部学校）+从即时诊断到动态干预：基于智慧纸笔的智能批改与个性化辅导实践 申报书.pdf | B105: 智慧纸笔 | C105: 四川省
A106: 第67号案例_成都石室东部新区实验学校-“人工智能+基础教育”典型应用案例申报书.pdf | B106: 数智作业系统 | C106: 四川省
A107: 第67号案例_成都石室东部新区实验学校-“人工智能+基础教育”典型应用案例申报书.pdf | B107: 精准教学大数据系统 | C107: 四川省
A108: 第68号案例_成都市实验小学+趣味化·个性化·智能化：“天天跳绳”App重塑小学体育作业新样态.docx | B108: 天天跳绳App | C108: 四川省
A109: 第69号案例_成都信息工程大学红樱实验学校+基于智能批阅系统的作业设计与批改实践申报书.docx | B109: 希沃作业学情采集分析系统 | C109: 四川省
A110: 第69号案例_成都信息工程大学红樱实验学校+基于智能批阅系统的作业设计与批改实践申报书.docx | B110: 判判智能批阅系统 | C110: 四川省
A111: 第70号案例_大同市云州区苏家寨中心学校曹宇香基于AI的小学数学精准化学习与辅助系统案例申报书.docx | B111: 智能作业设计与批改系统 | C111: 山西省
A112: 第71号案例_海盐高级中学+杨晶“人工智能+基础教育”典型应用场景案例申报书.docx | B112: AI作业生成系统 | C112: 浙江省
A113: 第73号案例_成都七中华溪AI助力高中英语数字化教学效能提升的实践研究.docx | B113: 天学网AI智能批改平台 | C113: 四川省
... A182: 第110号案例_人工智能+基础教育 应用案例 AI 慧眼识出入 无感智护校园安 申报书.docx | B182: 智慧校园请假系统 | C182: 陕西省
A183: 第112号案例_典型应用案例申报书-石外.docx | B183: #N/A | C183: 河北省
A184: 第113号案例_《人工智能+基础教育》全域校园人机伴生智慧管理模式申报书.pdf | B184: 钉钉AI | C184: 未提及
A185: 第113号案例_《人工智能+基础教育》全域校园人机伴生智慧管理模式申报书.pdf | B185: 通义千问大模型 | C185: 未提及
A186: 第114号案例_“人工智能+基础教育”典型应用场景案例申报书.pdf | B186: 红色智慧行政助理 | C186: 重庆市
A187: 第114号案例_“人工智能+基础教育”典型应用场景案例申报书.pdf | B187: 百度飞桨PaddlePaddle | C187: 重庆市
A188: 第115号案例_附件.docx | B188: #N/A | C188: 浙江省
A189: 第116号案例_山东师大附中案例申报书（智慧物联，用AI提升高中学校资产管理实效——以山东师范大学附属中学为例）.docx | B189: 锦大模型 | C189: 山东省
A190: 第116号案例_山东师大附中案例申报书（智慧物联，用AI提升高中学校资产管理实效——以山东师范大学附属中学为例）.docx | B190: 资产管理平台 | C190: 山东省
A191: 第117号案例_1.“人工智能+基础教育”典型应用场景案例申报书.docx | B191: 豆包 | C191: 重庆市
A192: 第117号案例_1.“人工智能+基础教育”典型应用场景案例申报书.docx | B192: 通义千问大模型 | C192: 重庆市
A193: 第117号案例_1.“人工智能+基础教育”典型应用场景案例申报书.docx | B193: 文心大模型 | C193: 重庆市
A194: 第117号案例_1.“人工智能+基础教育”典型应用场景案例申报书.docx | B194: 可灵AI | C194: 重庆市
A195: 第117号案例_1.“人工智能+基础教育”典型应用场景案例申报书.docx | B195: 即梦AI | C195: 重庆市
...

Sheet Sheet1
A1: 文件名 | B1: 处理时间 | C1: 案例编号 | D1: 案例名称 | E1: 学段 | F1: 学科 | G1: 地区 | H1: 应用场景（一级） | I1: 应用场景（二级） | J1: 培养方向 | K1: 潜在成效 | L1: 关键技术路径 | M1: 技术要素 | N1: 典型工具与平台形态 | O1: 产业应用现状 | P1: 优势和创新点
A2: 第01号案例_1温州市新田园小学 叶诗婧《数“算”生“动”：AI赋能下运算律教学的新样态》.pdf | B2: 46042.644 | C2: 1 | D2: 数“算”生“动”：AI赋能下运算律教学的新样态 | E2: 小学 | F2: 数学 | G2: 温州市 | H2: 助学 | I2: 智能辅导系统 | J2: 智育 | K2: 学生：深化算理理解、提升表达与推理能力；教师：实现精准诊断与即时干预；学校：形成可复制的“AI+概念教学”范式 | L2: 学习行为采集 → 学情诊断与画像生成 → 个性化反馈与辅导 → 学习改进 | M2: 数据采集层（多模态学习数据采集与融合） 画像诊断层（个性化画像生成、过程性反馈解释） 个性化学习层（即时生成反馈） | N2: 易点慧 AI 学伴 / AI 学习机（易点慧科技有限公司，案例01）；校本化智能辅导系统（未点名企业） | O2: 企业产品以“学习支持工具”为主，学校多通过校本化规则实现教学适配，整体处于规模化应用初期 | P2: AI点子图可视化 + AI说理，将抽象运算律转化为可操作模型，实现“理解—表达—诊断”闭环
A3: 第02号案例_2温州市新田园小学朱朝炜《三维联动：人工智能视域下小学足球运球游戏设计与研究》.pdf | B3: 46042.644 | C3: 2 | D3: 人工智能视域下“三维联动”小学足球运球游戏设计与实践 | E3: 小学 | F3: 体育 | G3: 温州市 | H3: 助学 | I3: 游戏化学习 | J3: 体育 | K3: 学生：提升足球运球技术、体能达标率与课堂参与度；教师：实现精准调控与动态反馈；学校：推动体育教学数字化转型与创新实践。 | L3: 数据采集 → 动态调整 → 多维反馈 | M3: 数据采集层（智慧手环、心率带、AI分析系统）；动态调整层（实时心率监测、体能负荷调控）；反馈层（多源数据融合的精准评价体系） | N3: 智慧体育设备（未点名企业） | O3: 企业产品以“智慧体育”与“游戏化教学”为主，整体处于数字化转型的探索阶段，具有较大的推广潜力。 | P3: 构建“技术-体能-应用”三维联动框架，通过游戏化教学实现技术、体能与应用的协同发展，填补传统教学中“数据缺失-调控盲目”的空白。
A4: 第03号案例_3【案例】从赋能到内生：智能评测驱动“教学评一致”的机理与路径探寻.pdf | B4: 46042.644 | C4: 3 | D4: 从赋能到内生：智能评测驱动下“教学评一致”的机理与路径探寻 | E4: 小学 | F4: 英语 | G4: 温州市 | H4: 助教 | I4: 智能学情诊断与个性化辅导 | J4: 智育 | K4: 学生：提升语音准确率、增强课堂参与度；教师：实现精准教学与动态调整；学校：形成可复制的教学评一致性模式 | L4: 数据采集 → 学情诊断与分析 → 个性化反馈与辅导 → 教学评一致性实现 | M4: 数据采集层（多模态数据采集与分析） 行为识别层（语音评测与互动分析） 画像诊断层（个性化学情报告生成） 智能策略层（动态教学调整与反馈） | N4: 易点慧语音型学习机（易点慧科技有限公司，案例03） | O4: 企业产品以“智能评测与个性化辅导工具”为主，已在多所小学规模化应用，整体处于推广阶段 | P4: 实现了智能评测从外部工具赋能到系统内生动力的转变，构建了“教学评一致性”的动态调整机制，提升了教学效率与学生语言应用能力
A5: 第04号案例_AI赋能地理课堂——七大洲轮廓记忆消消乐申报书.docx | B5: 46042.644 | C5: 4 | D5: AI赋能地理课堂——七大洲轮廓记忆消消乐 | E5: 初中 | F5: 地理 | G5: 重庆市璧山区 | H5: 助学 | I5: 智能辅导系统 | J5: 智育 | K5: 学生：提升知识点记忆效率，增强学习主动性；教师：提供即时反馈与个性化巩固工具；学校：探索AI与基础教育深度融合的实践思路。 | L5: 需求分析 → AI互动速记挑战网页开发 → 界面优化与课堂融合实践 → 持续反馈与迭代优化 | M5: 数据采集层（学生操作数据记录） 行为识别层（学习模式分析） 个性化学习层（即时反馈与挑战） | N5: AI互动速记挑战网页（未点名企业） | O5: 企业产品以“轻量化教育应用”为主，能够快速部署，适用于教育资源薄弱地区，整体处于推广阶段。 | P5: 将游戏化学习与地理知识结合，创新性地转变学习模式，提供零门槛的教育应用，促进学生主动学习与课堂互动。
C6: 5
C7: 6
A8: 第07号案例_案例申报书.docx | B8: 46042.644 | C8: 7 | D8: AI作为“认知协作者”赋能高中数学阅读精品课的跨学科构建与实践 | E8: 高中 | F8: 数学 | G8: 重庆市北碚区 | H8: 助教 | I8: 课堂管理 | J8: 智育 | K8: 学生：提升数学抽象能力、空间想象能力及科技伦理观念；教师：提高备课效率与课程质量；学校：推动基础教育资源的优质均衡发展。 | L8: 需求分析 → 课程设计 → AI赋能的设计流程与实践 → 课堂实施 → 课后评价与思辨引导 | M8: 数据采集层（AI工具DeepSeek用于内容整合与框架生成） 行为识别层（AI生成课堂任务与互动设计） 画像诊断层（AI生成思辨性问题） | N8: DeepSeek（未点名企业）；可灵AI（未点名企业）；豆包（未点名企业） | O8: 该模式具有极强的可复制性，适用于各学科、各学段的精品课、公开课及常规课的教学设计，整体处于推广应用阶段。 | P8: 将AI作为“认知协作者”嵌入课程开发全流程，促进教师角色转变为方案设计者与质量把控者，创新性地引入“数字人”模拟学生进行互动，提升课堂沉浸感与互动性。
A9: 第08号案例_8川外科中-《AI智教分析：教学相长的协同创新》案例.docx | B9: 46042.644 | C9: 8 | D9: AI智教分析：教学相长的协同创新 | E9: 未提及 | F9: 未提及 | G9: 重庆高新区 | H9: 助学 | I9: 智能辅导系统 | J9: 智育 | K9: 学生：实现个性化学习与成长；教师：提升教学质量与策略调整能力；学校：推动教育资源的合理配置与管理决策的科学化。 | L9: 数据采集与汇聚 → 学生与教师数字画像构建 → 个性化教学与精准评估 → 教学决策优化 | M9: 数据采集层（多源数据采集与融合） 画像诊断层（学生与教师数字画像生成、学习行为分析） 智能策略层（个性化学习路径推荐、教学策略调整） | N9: 未来教室（未点名企业）；壹教云系统（未点名企业） | O9: 企业产品以'学习支持工具'为主，学校通过智能化教学体系实现个性化教育，整体处于探索与应用阶段。 | P9: 构建数据驱动的智能教育生态，形成学生与教师之间的动态反馈闭环，实现个性化教学与精准评估的有效结合。
A10: 第09号案例_贾晓莹“人工智能 基础教育”典型应用场景案例(2).docx | B10: 46042.644 | C10: 9 | D10: 盛情邀约——海河中学130周年校庆邀请函设计 | E10: 初中 | F10: 美术 | G10: 天津 | H10: 助学 | I10: 情境式学习 | J10: 美育 | K10: 学生：掌握折叠式立体请柬的设计与制作技能，理解校史内涵，建立对母校的情感认同；教师：探索融合教学模式；学校：通过学生创作的邀请函传递校庆温度，增强师生、家校的凝聚力。 | L10: 需求分析 → 技术研发与个性化定制 → 应用优化 → 案例创新突破 | M10: 数据采集层（师生访谈、家校问卷） 行为识别层（教师与学生的互动分析） 智能策略层（个性化教学策略生成） 个性化学习层（动态推送适配资源） | N10: 梦AI软件（未点名企业）；豆包软件（未点名企业）；剪映AI扩图（未点名企业）；百度文心一格（未点名企业） | O10: 企业产品以“学习支持工具”为主，学校多通过校本化规则实现教学适配，整体处于规模化应用初期。 | P10: 突破传统单向灌输，构建双师协同与项目式学习，利用AI技术提升课堂参与度，增强学生对校史文化的理解与情感共鸣。
A11: 第10号案例_10人工智能赋能初中英语互动教学：破解课程参与难度，提升教学效能.docx | B11: 46042.644 | C11: 10 | D11: 人工智能赋能初中英语互动教学：破解课程参与难度，提升教学效能 | E11: 初中 | F11: 英语 | G11: 重庆市璧山区 | H11: 助学 | I11: 智能辅导系统 | J11: 智育 | K11: 学生：提升课堂参与度与英语能力；教师：实现实时反馈与精准教学；学校：形成可复制的AI教学模式 | L11: 需求分析 → 技术适配 → 应用优化 → 教学反馈 | M11: 数据采集层（实时语音评测、班级学情报告） 行为识别层（学生参与率与正确率统计） 个性化学习层（智能分层推送、个性化巩固练习） | N11: AI语音互动平台（科大讯飞智慧课堂，未点名企业） | O11: 企业产品以"学习支持工具"为主，学校多通过校本化规则实现教学适配，整体处于规模化应用初期 | P11: 重构低压力高互动教学模式，提升学生开口率与参与度，确保个性化教学落地，适合薄弱学校推广
A12: 第11号案例_申报书 隆昌市向阳路小学 黎恩旭 《用彩墨画鱼》.docx | B12: 46042.644 | C12: 11 | D12: AI赋能跨学科融合：小学美术《用彩墨画鱼》全流程智能教学实践 | E12: 小学 | F12: 美术 | G12: 隆昌市 | H12: 助学 | I12: 智能辅导系统 | J12: 美育 | K12: 学生：提升审美感知、艺术表现与文化理解能力；教师：实现跨学科教学的有效融合；学校：形成可复制的‘AI+学科’教学模式，推动基础教育智能化转型。 | L12: 需求分析 → 技术适配与定制 → 全流程应用实践与优化 → 应用迭代优化 | M12: 数据采集层（动态赋能模块、语音合成模块） 行为识别层（互动答题系统、知识认知场景化） 画像诊断层（虚拟展馆展示学生作品） | N12: 即梦AI（未标注）；希沃白板（未标注）；微信‘元美’小程序（未标注）；Photoshop（未标注）；剪映（未标注） | O12: 该案例已在本校四年级美术课堂落地，具备大规模推广的成熟条件与广阔前景，推动基础教育数字化转型。 | P12: 首创‘AI+IP主题+跨学科三维融合’教学范式，通过动态演示与虚拟展馆展示，打破学科壁垒，实现知识的可视化与互动化，提升学生的参与感与创作成就感。
A13: 第12号案例_12重庆市第八中学校+从“动手实践”到“真实探究”：生成式AI支持下中学科学课程的五轮迭代研究.pdf | B13: 46042.645 | C13: 12 | D13: 从“动手实践”到“真实探究”：生成式AI支持下中学科学课程的五轮迭代研究 | E13: 初中 | F13: 科学 | G13: 重庆 | H13: 助教 | I13: 教学分析 | J13: 智育 | K13: 学生：提升科学探究能力与创新意识；教师：实现教学设计优化与专业成长；学校：推动STEM教育的本土化发展与教育资源均衡。 | L13: 课程设计优化 → 教师反思与实践 → 生成式AI支持 → 学生探究与反馈 | M13: 数据采集层（学习过程记录、课堂实录） 行为识别层（学生探究行为分析） 画像诊断层（教师教学效果评估） 个性化学习层（AI辅助个性化探究路径） | N13: 基础大模型（DeepSeek，未标注） | O13: 企业产品以“AI辅助教学工具”为主，学校通过专家指导与AI支持实现教学适配，整体处于推广应用阶段。 | P13: 构建了“教师—专家—AI—学生学习证据”协同成长框架，系统揭示了教师在专家指导与生成式AI支持下的课程迭代与专业成长路径，推动了课堂教学由“讲授—模仿”向“探究—共创”的转型。
A14: 第13号案例_13九原区第一实验小学 高嘉彤 “人工智能+基础教育”典型应用场景案例”.pdf | B14: 46042.645 | C14: 13 | D14: AI赋能课堂组织管理：助力《圆的周长》探究式教学 | E14: 小学 | F14: 数学 | G14: 九原区 | H14: 助教 | I14: 课堂管理 | J14: 智育 | K14: 学生：提升课堂参与度与学习效率；教师：减轻数据统计负担，更专注于教学引导；学校：实现课堂组织管理的高效化与科学化。 | L14: 课堂导入视频生成 → 学生互动程序生成 → 实时反馈与评价 → 教学决策优化 | M14: 数据采集层（即时反馈数据采集与可视化管理） 行为识别层（学生参与度分析） 个性化学习层（即时生成反馈与评价） | N14: 即梦AI（未标注）；豆包（未标注）；问卷星（未标注） | O14: 该案例在基础教育领域处于积极探索阶段，利用轻量级AI工具实现课堂教学的数字化转型，具备较强的推广潜力。 | P14: 通过集成多种AI工具，实现了从传统教学模式向数据驱动探究式教学的转变，构建了低门槛的智能教学环境，提升了课堂参与率与反馈效率。
A15: 第14号案例_14铜梁中学 基于“AI+项目化”的铜梁中学“数项融合”校本课程的开发与应用实践(1026).pdf | B15: 46042.645 | C15: 14 | D15: 基于“AI+项目化”的铜梁中学“数项融合”高中物理校本课程的开发与应用实践 | E15: 高中 | F15: 物理 | G15: 重庆市 | H15: 助教 | I15: 智能辅导系统 | J15: 智育 | K15: 学生：提升实践能力与创新思维；教师：增强AI辅助教学能力；学校：推动课程改革与教学质量提升。 | L15: AI辅助课堂教学与互动 → 虚拟实验教学 → 智能学情诊断与个性化辅导 → 课程开发与应用 | M15: 数据采集层（多模态学习数据采集与融合） 行为识别层（学习意图识别、学习路径偏差检测） 画像诊断层（个性化画像生成、过程性反馈解释） 个性化学习层（即时生成反馈） | N15: AIGC（未标注）；国家智慧教育平台（未标注） | O15: 企业产品以“学习支持工具”为主，学校通过校本化规则实现教学适配，整体处于规模化应用初期。 | P15: 通过“AI+项目化”教学模式，构建了多元智慧学习场景，促进了物理教学的实践与创新，形成了鲜明的项目驱动与AI赋能特色。
A16: 第15号案例_15重庆市第八中学校+AI+SFK交互式人工智能教具应用与推广.pdf | B16: 46042.645 | C16: 15 | D16: AI+SFK交互式人工智能教具应用与推广 | E16: 初中 | F16: 人工智能 | G16: 重庆市 | H16: 助教 | I16: 教学辅助 | J16: 智育 | K16: 学生：激发对人工智能的兴趣，培养计算思维与探究能力；教师：降低教学门槛，提高教学效率；学校：形成可复制、可推广的AI教育新模式。 | L16: 需求分析 → 教具设计与开发 → 应用实践与反馈 → 持续优化与推广 | M16: 理念创新（可触摸的思维）；结构创新（模块化集成）；外观创新（双面布局）；资源创新（项目式教学资源库） | N16: AI+SFK交互式人工智能教具（未点名企业） | O16: 已在重庆市50余所中小学推广应用，整体处于规模化应用阶段，形成了“本校-集团-区域”三级推广网络。 | P16: 通过软硬件协同、简化操作、双面布局等创新，实现了从传统编程到理解底层逻辑的跨越，提升了教学的互动性与趣味性。
A17: 第16号案例_16重庆市人民小学校 革新发展性评价 培育“五星好少年”-申报书.pdf | B17: 46042.645 | C17: 16 | D17: 革新发展性评价 培育“五星好少年” | E17: 小学 | F17: 未提及 | G17: 重庆市 | H17: 助评 | I17: 综合素质评价 | J17: 德智体美劳 | K17: 学生：全面发展、个性化成长；教师：减轻评价负担、精准指导；学校：提升育人效能、获得多项荣誉 | L17: 数据采集 → 评价体系构建 → 个性化成长档案生成 → 过程赋能 | M17: 数据采集层（多模态数据采集与融合） 行为识别层（学生表现实时评价） 画像诊断层（个性化成长画像生成） | N17: yolo7（未标注企业）；劳动萌主小程序（未标注企业） | O17: 案例已在重庆市人民小学教育集团全面应用，形成可复制的实施方案，具有显著的社会效益与人才发展价值 | P17: 创新性地将物联网数据采集与人工智能算法深度整合，形成全流程技术解决方案，实现综合性、过程性的学生评价的规模化、常态化实施
A18: 第17号案例_17重庆市第八中学校+AI+校园全域智学成长平台.pdf | B18: 46042.646 | C18: 17 | D18: AI+校园全域智学成长平台 | E18: 高中 | F18: 未提及 | G18: 重庆市 | H18: 助学 | I18: 智能学情诊断与个性化辅导 | J18: 智育 | K18: 学生：实现个性化学习规划，提升学习效率与信心；教师：减轻批改负担，提升教学质量；学校：构建公平优质的教育新生态。 | L18: 数据采集 → 动态学情画像构建 → 精准教学干预 → 个性化学习路径优化 | M18: 数据采集层（动态学情画像构建） 行为识别层（学生思维路径与认知负荷分析） 画像诊断层（多维动态学生能力画像） 智能策略层（个性化学习路径推荐） | N18: AI+校园全域智学成长平台（未点名企业） | O18: 企业产品以“学习支持工具”为主，已在重庆市部分区县高中成功落地，具备低成本、高效益的规模化推广潜力。 | P18: 重构基于全量数据融合的精准教学新范式，打破数据孤岛，实现动态能力画像与个性化教学干预，提升教学质量与效率。
A19: 第18号案例_18重庆市第八中学校+AI赋能教育评价创新——基于三创教育理念的任务链与成长画像实践.pdf | B19: 46042.646 | C19: 18 | D19: AI赋能教育评价创新——基于三创教育理念的任务链与成长画像实践 | E19: 初中 | F19: 未提及 | G19: 重庆市 | H19: 助评 | I19: 学生成长数据分析与预警 | J19: 智育 | K19: 学生：提升学习主动性与自我反思能力；教师：增强精准教学能力；学校：推动‘教、学、评’一体化改革，形成可复制的教育评价创新路径。 | L19: 学习行为采集 → 学习过程分析 → 成长画像生成 → 个性化反馈 | M19: 数据采集层（多模态行为数据自动采集） 智能分析层（自然语言理解与模式识别算法） 画像诊断层（个体发展曲线与班级群体分析生成） 反馈与应用层（项目实施报告与个人成长画像查看） | N19: YEEAI系统（北京易知简教育科技有限公司，案例18） | O19: 企业产品以‘教育评价工具’为主，学校通过校企合作实现教学适配，整体处于规模化应用初期。 | P19: 构建AI支持的任务链学习模式，实现动态评价与个性化反馈，促进教师与学生的双向赋能，形成‘理念引领、技术支撑、场景共建’的协同创新机制。
... A25: 第24号案例_24北京十一学校顺义学校（杨镇一中）丁洁 指数衰减模型的跨学科探索——AI辅助下的核污水放射性衰变分析.docx | B25: 46042.647 | C25: 24 | D25: 指数衰减模型的跨学科探索——AI辅助下的核污水放射性衰变分析 | E25: 高中 | F25: 数学/物理/环境科学 | G25: 北京 | H25: 助学 | I25: 智能辅导系统 | J25: 智育 | K25: 学生：提升高阶思维能力、科学素养与批判性思维；教师：实现精准备课与教学；学校：推动跨学科项目式学习的实施。 | L25: 数据整合与精准学情分析 → 动态探究与高效互动 → 拓展探究与能力培养 | M25: 数据采集层（跨学科数据整合、实时半衰期数据获取） 行为识别层（学情分析与反馈） 个性化学习层（AI工具辅助学习与资源推荐） | N25: 豆包（未点名企业）；Deepseek（未点名企业）；GeoGebra（未点名企业） | O25: 案例展示了AI技术在基础教育中的系统性应用，推动了跨学科教学的探索与实践，整体处于推广阶段。 | P25: 通过真实社会问题驱动，整合数学、物理与环境科学，利用AI工具提升学生的自主探究能力与批判性思维，体现了STEM教育与项目式学习的核心思想。
C26: 25
A27: 第26号案例_26重庆市第八中学校+人工智能赋能学生评价——AI助力教师撰写评语的实践探索.pdf | B27: 46042.647 | C27: 26 | D27: 人工智能赋能学生评价——AI助力教师撰写评语的实践探索 | E27: 初中 | F27: 未提及 | G27: 重庆市 | H27: 助评 | I27: 学生评估 | J27: 德育 | K27: 学生：获得个性化、鼓励性的评语；教师：减轻评语撰写负担，提高工作效率；学校：提升教育评价质量与教师满意度。 | L27: AI评语生成 → 教师审核与润色 → 个性化反馈 | M27: 数据采集层（学生信息与关键词输入） 行为识别层（评语生成模型） 个性化学习层（教师个性化修改与润色） | N27: 豆包（未标注企业）；AA班级助手（未标注企业） | O27: 企业产品以“评语撰写工具”为主，学校通过AI辅助实现评语个性化，整体处于推广应用阶段。 | P27: 通过AI辅助撰写评语，显著提高教师工作效率，减轻重复性劳动，促进教师对教育语言的反思与表达能力提升，同时确保评语的个性化与温度。
A28: 第27号案例_【申报书】西南大学附属中学校-马彬琼-“缙云AI”历史主观题智能批阅平台.docx | B28: 46042.647 | C28: 27 | D28: 缙云AI历史主观题智能批阅平台 | E28: 初中 | F28: 历史 | G28: 重庆市 | H28: 助评 | I28: 学生评估 | J28: 智育 | K28: 学生：明确主观题错因及提分路径；教师：减轻评阅负担、提高评阅效率；教育管理者：优化学业质量评估、提升教学质量。 | L28: 需求分析 → 技术研发与实施 → 应用优化 → 案例创新突破 | M28: 数据采集层（历史主观题作答数据采集） 行为识别层（学生作答模式分析） 画像诊断层（个性化评分与反馈生成） 智能策略层（AI初评与教师复核协同） | N28: 缙云AI（未标注企业） | O28: 企业产品以'智能评阅工具'为主，已在多个省份推广，整体处于规模化应用阶段。 | P28: 突破了主观题传统人工评阅模式，实现全题型智能化评阅，减轻教师负担，提供实时反馈与精准诊断，满足学生个性化提分需求。
C29: 28
A30: 第29号案例_AI赋能：学生体质健康智能化管理平台的构建与实施案例.docx | B30: 46042.647 | C30: 29 | D30: AI赋能：学生体质健康智能化管理平台的构建与实施案例 | E30: 小学 | F30: 体育 | G30: 北京市西城区 | H30: 助学 | I30: 智能辅导系统 | J30: 体育 | K30: 学生：实现个性化体质健康管理与提升；教师：减轻工作负担，提升教学效果；学校：推动健康教育现代化，形成可复制的管理模式。 | L30: 数据采集 → 数据分析与评估 → 个性化干预 → 管理闭环 | M30: 数据采集层（智能设备自动化数据采集） 画像诊断层（动态更新的学生体质数据库） 个性化学习层（个性化体质报告与干预建议） | N30: 学生体质健康管理平台（未点名企业） | O30: 企业产品以“健康管理工具”为主，学校通过智能化手段实现数据驱动的健康管理，整体处于初步推广阶段。 | P30: 构建了“测、评、导、促”一体化闭环，推动体育教育从普适化向个性化转变，实现了数据驱动的精准干预与家校协同的新生态。
